Workbook

Sheet 통산 성적(~'23)
A1: ◎ 라스칼 통산 성적 (~'23 Season)
A2: 1. 타자 기록
A3: 이름 | B3: 게임수 | C3: 타율 | D3: 타석 | E3: 타수 | F3: 안타 | G3: 1루타 | H3: 2루타 | I3: 3루타 | J3: 홈런 | K3: 득점 | L3: 타점 | M3: 도루 | N3: 사사구 | O3: 삼진 | P3: 삼진률 | Q3: 장타율 | R3: 출루율 | S3: OPS | T3: 아웃 比 삼진률 | U3: 출루율 등수 | V3: OPS 등수
A4: 권강현 | B4: 6 | C4: {=F4/E4} -> 0 | D4: 1 | E4: 1 | F4: 0 | G4: 0 | H4: 0 | I4: 0 | J4: 0 | K4: 0 | L4: 0 | M4: 1 | N4: 0 | O4: 1 | P4: {=O4/D4} -> 1 | Q4: {=(G4*1+H4*2+I4*3+J4*4)/E4} -> 0 | R4: {=(F4+N4)/D4} -> 0 | S4: {=R4+Q4} -> 0 | T4: {=O4/(D4-(F4+N4))} -> 1 | U4: {=RANK(R4,$R$4:$R$24)} -> 20 | V4: {=RANK(S4,$S$4:$S$24)} -> 20
A5: 권혁진 | B5: 19 | C5: {=F5/E5} -> 0.23529412 | D5: 34 | E5: 17 | F5: 4 | G5: 4 | H5: 0 | I5: 0 | J5: 0 | K5: 6 | L5: 6 | M5: 3 | N5: 16 | O5: 7 | P5: {=O5/D5} -> 0.20588235 | Q5: {=(G5*1+H5*2+I5*3+J5*4)/E5} -> 0.23529412 | R5: {=(F5+N5)/D5} -> 0.58823529 | S5: {=R5+Q5} -> 0.82352941 | T5: {=O5/(D5-(F5+N5))} -> 0.5 | U5: {=RANK(R5,$R$4:$R$24)} -> 2 | V5: {=RANK(S5,$S$4:$S$24)} -> 10
A6: 김기태 | B6: 29 | C6: {=F6/E6} -> 0.55 | D6: 78 | E6: 60 | F6: 33 | G6: 24 | H6: 7 | I6: 2 | J6: 0 | K6: 35 | L6: 30 | M6: 24 | N6: 16 | O6: 5 | P6: {=O6/D6} -> 0.064102564 | Q6: {=(G6*1+H6*2+I6*3+J6*4)/E6} -> 0.73333333 | R6: {=(F6+N6)/D6} -> 0.62820513 | S6: {=R6+Q6} -> 1.3615385 | T6: {=O6/(D6-(F6+N6))} -> 0.17241379 | U6: {=RANK(R6,$R$4:$R$24)} -> 1 | V6: {=RANK(S6,$S$4:$S$24)} -> 2
A7: 김민석 | B7: 1 | C7: {=F7/E7} -> 0 | D7: 4 | E7: 4 | F7: 0 | G7: 0 | H7: 0 | I7: 0 | J7: 0 | K7: 0 | L7: 3 | M7: 0 | N7: 0 | O7: 0 | P7: {=O7/D7} -> 0 | Q7: {=(G7*1+H7*2+I7*3+J7*4)/E7} -> 0 | R7: {=(F7+N7)/D7} -> 0 | S7: {=R7+Q7} -> 0 | T7: {=O7/(D7-(F7+N7))} -> 0 | U7: {=RANK(R7,$R$4:$R$24)} -> 20 | V7: {=RANK(S7,$S$4:$S$24)} -> 20
A8: 김범희 | B8: 30 | C8: {=F8/E8} -> 0.36666667 | D8: 75 | E8: 60 | F8: 22 | G8: 14 | H8: 5 | I8: 3 | J8: 0 | K8: 22 | L8: 24 | M8: 13 | N8: 14 | O8: 14 | P8: {=O8/D8} -> 0.18666667 | Q8: {=(G8*1+H8*2+I8*3+J8*4)/E8} -> 0.55 | R8: {=(F8+N8)/D8} -> 0.48 | S8: {=R8+Q8} -> 1.03 | T8: {=O8/(D8-(F8+N8))} -> 0.35897436 | U8: {=RANK(R8,$R$4:$R$24)} -> 8 | V8: {=RANK(S8,$S$4:$S$24)} -> 6
A9: 김병진 | B9: 17 | C9: {=F9/E9} -> 0.22580645 | D9: 38 | E9: 31 | F9: 7 | G9: 6 | H9: 1 | I9: 0 | J9: 0 | K9: 7 | L9: 4 | M9: 7 | N9: 7 | O9: 15 | P9: {=O9/D9} -> 0.39473684 | Q9: {=(G9*1+H9*2+I9*3+J9*4)/E9} -> 0.25806452 | R9: {=(F9+N9)/D9} -> 0.36842105 | S9: {=R9+Q9} -> 0.62648557 | T9: {=O9/(D9-(F9+N9))} -> 0.625 | U9: {=RANK(R9,$R$4:$R$24)} -> 15 | V9: {=RANK(S9,$S$4:$S$24)} -> 16
A10: 김재영 | B10: 29 | C10: {=F10/E10} -> 0.51315789 | D10: 94 | E10: 76 | F10: 39 | G10: 28 | H10: 7 | I10: 3 | J10: 1 | K10: 40 | L10: 27 | M10: 47 | N10: 16 | O10: 8 | P10: {=O10/D10} -> 0.085106383 | Q10: {=(G10*1+H10*2+I10*3+J10*4)/E10} -> 0.72368421 | R10: {=(F10+N10)/D10} -> 0.58510638 | S10: {=R10+Q10} -> 1.3087906 | T10: {=O10/(D10-(F10+N10))} -> 0.20512821 | U10: {=RANK(R10,$R$4:$R$24)} -> 3 | V10: {=RANK(S10,$S$4:$S$24)} -> 3
A11: 김태양 | B11: 16 | C11: {=F11/E11} -> 0.28125 | D11: 36 | E11: 32 | F11: 9 | G11: 8 | H11: 1 | I11: 0 | J11: 0 | K11: 10 | L11: 9 | M11: 8 | N11: 4 | O11: 8 | P11: {=O11/D11} -> 0.22222222 | Q11: {=(G11*1+H11*2+I11*3+J11*4)/E11} -> 0.3125 | R11: {=(F11+N11)/D11} -> 0.36111111 | S11: {=R11+Q11} -> 0.67361111 | T11: {=O11/(D11-(F11+N11))} -> 0.34782609 | U11: {=RANK(R11,$R$4:$R$24)} -> 16 | V11: {=RANK(S11,$S$4:$S$24)} -> 13
A12: 김현철 | B12: 5 | C12: {=F12/E12} -> 0.16666667 | D12: 9 | E12: 6 | F12: 1 | G12: 1 | H12: 0 | I12: 0 | J12: 0 | K12: 1 | L12: 1 | M12: 1 | N12: 0 | O12: 1 | P12: {=O12/D12} -> 0.11111111 | Q12: {=(G12*1+H12*2+I12*3+J12*4)/E12} -> 0.16666667 | R12: {=(F12+N12)/D12} -> 0.11111111 | S12: {=R12+Q12} -> 0.27777778 | T12: {=O12/(D12-(F12+N12))} -> 0.125 | U12: {=RANK(R12,$R$4:$R$24)} -> 19 | V12: {=RANK(S12,$S$4:$S$24)} -> 19
A13: 김형준 | B13: 24 | C13: {=F13/E13} -> 0.51923077 | D13: 58 | E13: 52 | F13: 27 | G13: 12 | H13: 13 | I13: 1 | J13: 1 | K13: 18 | L13: 23 | M13: 8 | N13: 5 | O13: 5 | P13: {=O13/D13} -> 0.086206897 | Q13: {=(G13*1+H13*2+I13*3+J13*4)/E13} -> 0.86538462 | R13: {=(F13+N13)/D13} -> 0.55172414 | S13: {=R13+Q13} -> 1.4171088 | T13: {=O13/(D13-(F13+N13))} -> 0.19230769 | U13: {=RANK(R13,$R$4:$R$24)} -> 5 | V13: {=RANK(S13,$S$4:$S$24)} -> 1
A14: 김희제 | B14: 14 | C14: {=F14/E14} -> 0.16666667 | D14: 33 | E14: 24 | F14: 4 | G14: 3 | H14: 0 | I14: 1 | J14: 0 | K14: 10 | L14: 2 | M14: 5 | N14: 9 | O14: 11 | P14: {=O14/D14} -> 0.33333333 | Q14: {=(G14*1+H14*2+I14*3+J14*4)/E14} -> 0.25 | R14: {=(F14+N14)/D14} -> 0.39393939 | S14: {=R14+Q14} -> 0.64393939 | T14: {=O14/(D14-(F14+N14))} -> 0.55 | U14: {=RANK(R14,$R$4:$R$24)} -> 13 | V14: {=RANK(S14,$S$4:$S$24)} -> 14
A15: 남동수 | B15: 8 | C15: {=F15/E15} -> 0.15384615 | D15: 20 | E15: 13 | F15: 2 | G15: 2 | H15: 0 | I15: 0 | J15: 0 | K15: 3 | L15: 4 | M15: 1 | N15: 4 | O15: 7 | P15: {=O15/D15} -> 0.35 | Q15: {=(G15*1+H15*2+I15*3+J15*4)/E15} -> 0.15384615 | R15: {=(F15+N15)/D15} -> 0.3 | S15: {=R15+Q15} -> 0.45384615 | T15: {=O15/(D15-(F15+N15))} -> 0.5 | U15: {=RANK(R15,$R$4:$R$24)} -> 17 | V15: {=RANK(S15,$S$4:$S$24)} -> 17
... A24: 차현철 | B24: 7 | C24: {=F24/E24} -> 0.090909091 | D24: 16 | E24: 11 | F24: 1 | G24: 1 | H24: 0 | I24: 0 | J24: 0 | K24: 3 | L24: 0 | M24: 2 | N24: 2 | O24: 3 | P24: {=O24/D24} -> 0.1875 | Q24: {=(G24*1+H24*2+I24*3+J24*4)/E24} -> 0.090909091 | R24: {=(F24+N24)/D24} -> 0.1875 | S24: {=R24+Q24} -> 0.27840909 | T24: {=O24/(D24-(F24+N24))} -> 0.23076923 | U24: {=RANK(R24,$R$4:$R$24)} -> 18 | V24: {=RANK(S24,$S$4:$S$24)} -> 18
A25: 총합 | C25: {=F25/E25} -> 0.37962963 | D25: {=SUM(D4:D24)} -> 810 | E25: {=SUM(E4:E24)} -> 648 | F25: {=SUM(F4:F24)} -> 246 | G25: {=SUM(G4:G24)} -> 181 | H25: {=SUM(H4:H24)} -> 49 | I25: {=SUM(I4:I24)} -> 12 | J25: {=SUM(J4:J24)} -> 4 | K25: {=SUM(K4:K24)} -> 239 | ... O25: {=SUM(O4:O24)} -> 146 | P25: {=O25/D25} -> 0.18024691 | Q25: {=(G25*1+H25*2+I25*3+J25*4)/E25} -> 0.51080247 | R25: {=(F25+N25)/D25} -> 0.48024691 | S25: {=R25+Q25} -> 0.99104938
A27: 2. 투수 기록
A28: 이름 | B28: 게임수 | C28: 승 | D28: 패 | E28: 세 | F28: 타자 | G28: 타수 | H28: 이닝 | I28: 피안타 | J28: 피홈런 | K28: 볼넷 | L28: 사구 | M28: 탈삼진 | N28: 실점 | O28: 자책점 | P28: 방어율 | Q28: 제구 | R28: 피안타율 | S28: 경기/이닝 | T28: 이닝/K | U28: 수비성공률 | V28: WHIP
A29: 권강현 | B29: 14 | C29: 1 | D29: 2 | E29: 0 | F29: 75 | G29: 40 | H29: 6.7 | I29: 15 | J29: 0 | K29: 31 | L29: 4 | M29: 4 | N29: 35 | O29: 19 | P29: {=O29*9/H29} -> 25.522388 | Q29: {=(K29+L29)/H29} -> 5.2238806 | R29: {=I29/H29} -> 2.238806 | S29: {=H29/B29} -> 0.47857143 | T29: {=M29/H29} -> 0.59701493 | U29: {=O29/N29} -> 0.54285714 | V29: {=(I29+K29+L29)/H29} -> 7.4626866
A30: 김민석 | B30: 1 | C30: 0 | D30: 0 | E30: 0 | F30: 1 | G30: 0 | H30: 0 | I30: 0 | J30: 0 | K30: 1 | L30: 0 | M30: 0 | N30: 0 | O30: 0 | P30: 0 | Q30: - | R30: - | S30: {=H30/B30} -> 0 | T30: - | U30: - | V30: -
A31: 김병진 | B31: 9 | C31: 1 | D31: 2 | E31: 0 | F31: 113 | G31: 85 | H31: 13 | I31: 33 | J31: 3 | K31: 23 | L31: 5 | M31: 11 | N31: 48 | O31: 32 | P31: {=O31*9/H31} -> 22.153846 | Q31: {=(K31+L31)/H31} -> 2.1538462 | R31: {=I31/H31} -> 2.5384615 | S31: {=H31/B31} -> 1.4444444 | T31: {=M31/H31} -> 0.84615385 | U31: {=O31/N31} -> 0.66666667 | V31: {=(I31+K31+L31)/H31} -> 4.6923077
A32: 김형준 | B32: 19 | C32: 3 | D32: 3 | E32: 1 | F32: 151 | G32: 127 | H32: 27.333 | I32: 39 | J32: 0 | K32: 20 | L32: 4 | M32: 39 | N32: 36 | O32: 19 | P32: {=O32*9/H32} -> 6.2561739 | Q32: {=(K32+L32)/H32} -> 0.87805949 | R32: {=I32/H32} -> 1.4268467 | S32: {=H32/B32} -> 1.4385789 | T32: {=M32/H32} -> 1.4268467 | U32: {=O32/N32} -> 0.52777778 | V32: {=(I32+K32+L32)/H32} -> 2.3049062
A33: 류동현 | B33: 12 | C33: 0 | D33: 3 | E33: 0 | F33: 143 | G33: 101 | H33: 19 | I33: 41 | J33: 2 | K33: 38 | L33: 3 | M33: 21 | N33: 58 | O33: 41 | P33: {=O33*9/H33} -> 19.421053 | Q33: {=(K33+L33)/H33} -> 2.1578947 | R33: {=I33/H33} -> 2.1578947 | S33: {=H33/B33} -> 1.5833333 | T33: {=M33/H33} -> 1.1052632 | U33: {=O33/N33} -> 0.70689655 | V33: {=(I33+K33+L33)/H33} -> 4.3157895
A34: 박영준 | B34: 1 | C34: 0 | D34: 0 | E34: 0 | F34: 3 | G34: 2 | H34: 1 | I34: 1 | J34: 0 | K34: 1 | L34: 0 | M34: 1 | N34: 0 | O34: 0 | P34: 0 | Q34: {=(K34+L34)/H34} -> 1 | R34: {=I34/H34} -> 1 | S34: {=H34/B34} -> 1 | T34: {=M34/H34} -> 1 | U34: - | V34: {=(I34+K34+L34)/H34} -> 2
A35: 임지헌 | B35: 6 | C35: 2 | D35: 2 | E35: 0 | F35: 97 | G35: 53 | H35: 12.999967 | I35: 16 | J35: 1 | K35: 43 | L35: 0 | M35: 13 | N35: 35 | O35: 21 | P35: {=O35*9/H35} -> 14.538499 | Q35: {=(K35+L35)/H35} -> 3.3077008 | R35: {=I35/H35} -> 1.2307724 | S35: {=H35/B35} -> 2.1666611 | T35: {=M35/H35} -> 1.0000026 | U35: {=O35/N35} -> 0.6 | V35: {=(I35+K35+L35)/H35} -> 4.5384732
A36: 조태형 | B36: 24 | C36: 5 | D36: 8 | E36: 3 | F36: 390 | G36: 284 | H36: 54.999967 | I36: 102 | J36: 1 | K36: 90 | L36: 15 | M36: 86 | N36: 141 | O36: 95 | P36: {=O36*9/H36} -> 15.545464 | Q36: {=(K36+L36)/H36} -> 1.9090921 | R36: {=I36/H36} -> 1.8545466 | S36: {=H36/B36} -> 2.2916653 | T36: {=M36/H36} -> 1.5636373 | U36: {=O36/N36} -> 0.67375887 | V36: {=(I36+K36+L36)/H36} -> 3.7636386
A37: 총합 | B37: {=SUM(B29:B36)} -> 86 | C37: {=SUM(C29:C36)} -> 12 | D37: {=SUM(D29:D36)} -> 20 | E37: {=SUM(E29:E36)} -> 4 | F37: {=SUM(F29:F36)} -> 973 | G37: {=SUM(G29:G36)} -> 692 | H37: {=SUM(H29:H36)} -> 135.03293 | I37: {=SUM(I29:I36)} -> 247 | ... O37: {=SUM(O29:O36)} -> 227 | P37: {=O37*9/H37} -> 15.129642 | Q37: {=(K37+L37)/H37} -> 2.058757 | R37: {=I37/H37} -> 1.8291834 | S37: {=H37/B37} -> 1.5701504 | T37: {=M37/H37} -> 1.2959801 | U37: {=O37/N37} -> 0.64305949 | V37: {=(I37+K37+L37)/H37} -> 3.8879404

Sheet 통산 성적(~'25)
A1: ◎ 라스칼 통산 성적 (~'25 Season)
A2: 1. 타자 기록 | X2: 전년 대비
A3: 이름 | B3: 게임수 | C3: 타율 | D3: 타석 | E3: 타수 | F3: 안타 | G3: 1루타 | H3: 2루타 | I3: 3루타 | J3: 홈런 | K3: 득점 | L3: 타점 | M3: 도루 | N3: 사사구 | O3: 삼진 | P3: 삼진률 | Q3: 장타율 | R3: 출루율 | S3: OPS | T3: 아웃 比 삼진률 | U3: 출루율 등수 | V3: OPS 등수 | X3: 타율 | Y3: 삼진률 | Z3: 장타율 | AA3: 출루율 | AB3: OPS | AD3: 타석 | AE3: 타수
A4: 권강현 | B4: 36 | C4: {=F4/E4} -> 0.46268657 | D4: 81 | E4: 67 | F4: 31 | G4: 22 | H4: 4 | I4: 3 | J4: 2 | K4: 43 | L4: 26 | M4: 39 | N4: 11 | O4: 15 | P4: {=O4/D4} -> 0.18518519 | Q4: {=(G4*1+H4*2+I4*3+J4*4)/E4} -> 0.70149254 | R4: {=(F4+N4)/D4} -> 0.51851852 | S4: {=R4+Q4} -> 1.2200111 | T4: {=O4/(D4-(F4+N4))} -> 0.38461538 | U4: {=RANK(R4,$R$4:$R$26)} -> 7 | V4: {=RANK(S4,$S$4:$S$26)} -> 4 | X4: 0.46268657 | Y4: -0.81481481 | Z4: 0.70149254 | AA4: 0.51851852 | AB4: 1.2200111 | AD4: 60 | AE4: 51 | AG4: {=AB4*AD4} -> 73.200663 | AH4: {=X4*AE4} -> 23.597015
A5: 권혁진 | B5: 46 | C5: {=F5/E5} -> 0.39240506 | D5: 113 | E5: 79 | F5: 31 | G5: 15 | H5: 13 | I5: 2 | J5: 1 | K5: 38 | L5: 32 | M5: 23 | N5: 30 | O5: 20 | P5: {=O5/D5} -> 0.17699115 | Q5: {=(G5*1+H5*2+I5*3+J5*4)/E5} -> 0.64556962 | R5: {=(F5+N5)/D5} -> 0.53982301 | S5: {=R5+Q5} -> 1.1853926 | T5: {=O5/(D5-(F5+N5))} -> 0.38461538 | U5: {=RANK(R5,$R$4:$R$26)} -> 5 | V5: {=RANK(S5,$S$4:$S$26)} -> 5 | X5: 0.15711095 | Y5: -0.028891202 | Z5: 0.4102755 | AA5: -0.048412285 | AB5: 0.37793921 | AD5: 109 | AE5: 75 | AG5: {=AB5*AD5} -> 41.195374 | AH5: {=X5*AE5} -> 11.783321
A6: 김기태 | B6: 66 | C6: {=F6/E6} -> 0.54037267 | D6: 192 | E6: 161 | F6: 87 | G6: 59 | H6: 22 | I6: 5 | J6: 1 | K6: 75 | L6: 80 | M6: 50 | N6: 29 | O6: 12 | P6: {=O6/D6} -> 0.0625 | Q6: {=(G6*1+H6*2+I6*3+J6*4)/E6} -> 0.75776398 | R6: {=(F6+N6)/D6} -> 0.60416667 | S6: {=R6+Q6} -> 1.3619306 | T6: {=O6/(D6-(F6+N6))} -> 0.15789474 | U6: {=RANK(R6,$R$4:$R$26)} -> 1 | V6: {=RANK(S6,$S$4:$S$26)} -> 1 | X6: -0.0096273292 | Y6: -0.0016025641 | Z6: 0.024430642 | AA6: -0.024038462 | AB6: 0.26693064 | AD6: 176 | AE6: 150 | AG6: {=AB6*AD6} -> 46.979793 | AH6: {=X6*AE6} -> -1.4440994
A7: 김민석 | B7: 15 | C7: {=F7/E7} -> 0.33333333 | D7: 31 | E7: 24 | F7: 8 | G7: 6 | H7: 1 | I7: 1 | J7: 0 | K7: 11 | L7: 11 | M7: 9 | N7: 7 | O7: 8 | P7: {=O7/D7} -> 0.25806452 | Q7: {=(G7*1+H7*2+I7*3+J7*4)/E7} -> 0.45833333 | R7: {=(F7+N7)/D7} -> 0.48387097 | S7: {=R7+Q7} -> 0.9422043 | T7: {=O7/(D7-(F7+N7))} -> 0.5 | U7: {=RANK(R7,$R$4:$R$26)} -> 10 | V7: {=RANK(S7,$S$4:$S$26)} -> 11 | X7: 0.33333333 | Y7: 0.25806452 | Z7: 0.45833333 | AA7: 0.48387097 | AB7: 0.9422043 | AD7: 11 | AE7: 11 | AG7: {=AB7*AD7} -> 10.364247 | AH7: {=X7*AE7} -> 3.6666667
A8: 김범희 | B8: 53 | C8: {=F8/E8} -> 0.37755102 | D8: 128 | E8: 98 | F8: 37 | G8: 26 | H8: 7 | I8: 3 | J8: 1 | K8: 41 | L8: 36 | M8: 21 | N8: 28 | O8: 25 | P8: {=O8/D8} -> 0.1953125 | Q8: {=(G8*1+H8*2+I8*3+J8*4)/E8} -> 0.54081633 | R8: {=(F8+N8)/D8} -> 0.5078125 | S8: {=R8+Q8} -> 1.0486288 | T8: {=O8/(D8-(F8+N8))} -> 0.3968254 | U8: {=RANK(R8,$R$4:$R$26)} -> 8 | V8: {=RANK(S8,$S$4:$S$26)} -> 8 | X8: 0.010884354 | Y8: 0.0086458333 | Z8: -0.0091836735 | AA8: 0.0278125 | AB8: 0.051930713 | AD8: 34 | AE8: 22 | AG8: {=AB8*AD8} -> 1.7656443 | AH8: {=X8*AE8} -> 0.23945578
A9: 김병진 | B9: 35 | C9: {=F9/E9} -> 0.3 | D9: 78 | E9: 70 | F9: 21 | G9: 17 | H9: 4 | I9: 0 | J9: 0 | K9: 20 | L9: 13 | M9: 24 | N9: 12 | O9: 23 | P9: {=O9/D9} -> 0.29487179 | Q9: {=(G9*1+H9*2+I9*3+J9*4)/E9} -> 0.35714286 | R9: {=(F9+N9)/D9} -> 0.42307692 | S9: {=R9+Q9} -> 0.78021978 | T9: {=O9/(D9-(F9+N9))} -> 0.51111111 | U9: {=RANK(R9,$R$4:$R$26)} -> 18 | V9: {=RANK(S9,$S$4:$S$26)} -> 18 | X9: 0.074193548 | Y9: -0.099865047 | Z9: 0.099078341 | AA9: 0.05465587 | AB9: 0.26232504
A10: 김상훈 | B10: 22 | C10: {=F10/E10} -> 0.43137255 | D10: 62 | E10: 51 | F10: 22 | G10: 17 | H10: 5 | I10: 0 | J10: 0 | K10: 15 | L10: 19 | M10: 18 | N10: 11 | O10: 3 | P10: {=O10/D10} -> 0.048387097 | Q10: {=(G10*1+H10*2+I10*3+J10*4)/E10} -> 0.52941176 | R10: {=(F10+N10)/D10} -> 0.53225806 | S10: {=R10+Q10} -> 1.0616698 | T10: {=O10/(D10-(F10+N10))} -> 0.10344828 | U10: {=RANK(R10,$R$4:$R$26)} -> 6 | V10: {=RANK(S10,$S$4:$S$26)} -> 7 | X10: -0.081785346 | Y10: -0.036719286 | Z10: -0.19427245 | AA10: -0.052848318 | AB10: -0.43833017
A11: 김재영 | B11: 72 | C11: {=F11/E11} -> 0.51851852 | D11: 205 | E11: 162 | F11: 84 | G11: 63 | H11: 13 | I11: 9 | J11: 1 | K11: 85 | L11: 58 | M11: 95 | N11: 37 | O11: 17 | P11: {=O11/D11} -> 0.082926829 | Q11: {=(G11*1+H11*2+I11*3+J11*4)/E11} -> 0.74074074 | R11: {=(F11+N11)/D11} -> 0.5902439 | S11: {=R11+Q11} -> 1.3309846 | T11: {=O11/(D11-(F11+N11))} -> 0.20238095 | U11: {=RANK(R11,$R$4:$R$26)} -> 2 | V11: {=RANK(S11,$S$4:$S$26)} -> 2 | X11: 0.0053606238 | Y11: -0.0021795537 | Z11: 0.01705653 | AA11: 0.0051375195 | AB11: -0.16901536 | AD11: 158 | AE11: 126 | AG11: {=AB11*AD11} -> -26.704426 | AH11: {=X11*AE11} -> 0.6754386
A12: 김태양 | B12: 50 | C12: {=F12/E12} -> 0.33663366 | D12: 121 | E12: 101 | F12: 34 | G12: 31 | H12: 3 | I12: 0 | J12: 0 | K12: 41 | L12: 25 | M12: 28 | N12: 20 | O12: 22 | P12: {=O12/D12} -> 0.18181818 | Q12: {=(G12*1+H12*2+I12*3+J12*4)/E12} -> 0.36633663 | R12: {=(F12+N12)/D12} -> 0.44628099 | S12: {=R12+Q12} -> 0.81261763 | T12: {=O12/(D12-(F12+N12))} -> 0.32835821 | U12: {=RANK(R12,$R$4:$R$26)} -> 14 | V12: {=RANK(S12,$S$4:$S$26)} -> 17 | X12: 0.055383663 | Y12: -0.04040404 | Z12: 0.053836634 | AA12: 0.085169881 | AB12: 0.22255551
A13: 김현철 | B13: 28 | C13: {=F13/E13} -> 0.34210526 | D13: 56 | E13: 38 | F13: 13 | G13: 10 | H13: 2 | I13: 1 | J13: 0 | K13: 21 | L13: 11 | M13: 15 | N13: 11 | O13: 4 | P13: {=O13/D13} -> 0.071428571 | Q13: {=(G13*1+H13*2+I13*3+J13*4)/E13} -> 0.44736842 | R13: {=(F13+N13)/D13} -> 0.42857143 | S13: {=R13+Q13} -> 0.87593985 | T13: {=O13/(D13-(F13+N13))} -> 0.125 | U13: {=RANK(R13,$R$4:$R$26)} -> 16 | V13: {=RANK(S13,$S$4:$S$26)} -> 14 | X13: 0.1754386 | Y13: -0.03968254 | Z13: 0.28070175 | AA13: 0.31746032 | AB13: 0.59816207 | AD13: -15 | AE13: -25 | AG13: {=AB13*AD13} -> -8.9724311 | AH13: {=X13*AE13} -> -4.3859649
A14: 김형준 | B14: 54 | C14: {=F14/E14} -> 0.48760331 | D14: 145 | E14: 121 | F14: 59 | G14: 35 | H14: 21 | I14: 2 | J14: 1 | K14: 45 | L14: 51 | M14: 22 | N14: 23 | O14: 6 | P14: {=O14/D14} -> 0.04137931 | Q14: {=(G14*1+H14*2+I14*3+J14*4)/E14} -> 0.71900826 | R14: {=(F14+N14)/D14} -> 0.56551724 | S14: {=R14+Q14} -> 1.2845255 | T14: {=O14/(D14-(F14+N14))} -> 0.095238095 | U14: {=RANK(R14,$R$4:$R$26)} -> 3 | V14: {=RANK(S14,$S$4:$S$26)} -> 3 | X14: -0.031627463 | Y14: -0.044827586 | Z14: -0.14637635 | AA14: 0.013793103 | AB14: -0.12733347 | AD14: 67 | AE14: 61 | AG14: {=AB14*AD14} -> -8.5313424 | AH14: {=X14*AE14} -> -1.9292753
A15: 남동수 | B15: 47 | C15: {=F15/E15} -> 0.27058824 | D15: 115 | E15: 85 | F15: 23 | G15: 20 | H15: 3 | I15: 0 | J15: 0 | K15: 27 | L15: 24 | M15: 18 | N15: 25 | O15: 33 | P15: {=O15/D15} -> 0.28695652 | Q15: {=(G15*1+H15*2+I15*3+J15*4)/E15} -> 0.30588235 | R15: {=(F15+N15)/D15} -> 0.4173913 | S15: {=R15+Q15} -> 0.72327366 | T15: {=O15/(D15-(F15+N15))} -> 0.49253731 | U15: {=RANK(R15,$R$4:$R$26)} -> 19 | V15: {=RANK(S15,$S$4:$S$26)} -> 20 | X15: 0.11674208 | Y15: -0.063043478 | Z15: 0.1520362 | AA15: 0.1173913 | AB15: 0.2694275 | AD15: 40 | AE15: 25 | AG15: {=AB15*AD15} -> 10.7771 | AH15: {=X15*AE15} -> 2.918552
A16: 류동현 | B16: 45 | C16: {=F16/E16} -> 0.35211268 | D16: 84 | E16: 71 | F16: 25 | G16: 18 | H16: 7 | I16: 0 | J16: 0 | K16: 24 | L16: 25 | M16: 16 | N16: 12 | O16: 13 | P16: {=O16/D16} -> 0.1547619 | Q16: {=(G16*1+H16*2+I16*3+J16*4)/E16} -> 0.45070423 | R16: {=(F16+N16)/D16} -> 0.44047619 | S16: {=R16+Q16} -> 0.89118042 | T16: {=O16/(D16-(F16+N16))} -> 0.27659574 | U16: {=RANK(R16,$R$4:$R$26)} -> 15 | V16: {=RANK(S16,$S$4:$S$26)} -> 13 | X16: -0.022887324 | Y16: 0.011904762 | Z16: -0.049295775 | AA16: -0.083333333 | AB16: -0.053264029 | AD16: 48 | AE16: 39 | AG16: {=AB16*AD16} -> -2.5566734 | AH16: {=X16*AE16} -> -0.89260563
A17: 박영준 | B17: 43 | C17: {=F17/E17} -> 0.37078652 | D17: 117 | E17: 89 | F17: 33 | G17: 26 | H17: 3 | I17: 4 | J17: 0 | K17: 37 | L17: 18 | M17: 35 | N17: 26 | O17: 19 | P17: {=O17/D17} -> 0.16239316 | Q17: {=(G17*1+H17*2+I17*3+J17*4)/E17} -> 0.49438202 | R17: {=(F17+N17)/D17} -> 0.5042735 | S17: {=R17+Q17} -> 0.99865553 | T17: {=O17/(D17-(F17+N17))} -> 0.32758621 | U17: {=RANK(R17,$R$4:$R$26)} -> 9 | V17: {=RANK(S17,$S$4:$S$26)} -> 9 | X17: 0.070786517 | Y17: -0.17094017 | Z17: 0.094382022 | AA17: 0.087606838 | AB17: 0.18198886 | AD17: 59 | AE17: 37 | AG17: {=AB17*AD17} -> 10.737343 | AH17: {=X17*AE17} -> 2.6191011
A18: 박재현 | B18: 56 | C18: {=F18/E18} -> 0.40186916 | D18: 126 | E18: 107 | F18: 43 | G18: 35 | H18: 6 | I18: 1 | J18: 1 | K18: 29 | L18: 23 | M18: 15 | N18: 15 | O18: 19 | P18: {=O18/D18} -> 0.15079365 | Q18: {=(G18*1+H18*2+I18*3+J18*4)/E18} -> 0.5046729 | R18: {=(F18+N18)/D18} -> 0.46031746 | S18: {=R18+Q18} -> 0.96499036 | T18: {=O18/(D18-(F18+N18))} -> 0.27941176 | U18: {=RANK(R18,$R$4:$R$26)} -> 12 | V18: {=RANK(S18,$S$4:$S$26)} -> 10 | X18: -0.11425987 | Y18: -0.011368511 | Z18: -0.17274646 | AA18: -0.10725011 | AB18: -0.31834298 | AD18: 86 | AE18: 73 | AG18: {=AB18*AD18} -> -27.377496 | AH18: {=X18*AE18} -> -8.3409708
A19: 백정철 | B19: 39 | C19: {=F19/E19} -> 0.34117647 | D19: 105 | E19: 85 | F19: 29 | G19: 25 | H19: 1 | I19: 1 | J19: 2 | K19: 27 | L19: 32 | M19: 12 | N19: 16 | O19: 13 | P19: {=O19/D19} -> 0.12380952 | Q19: {=(G19*1+H19*2+I19*3+J19*4)/E19} -> 0.44705882 | R19: {=(F19+N19)/D19} -> 0.42857143 | S19: {=R19+Q19} -> 0.87563025 | T19: {=O19/(D19-(F19+N19))} -> 0.21666667 | U19: {=RANK(R19,$R$4:$R$26)} -> 16 | V19: {=RANK(S19,$S$4:$S$26)} -> 15 | X19: -0.041176471 | Y19: 0.023809524 | Z19: 0.064705882 | AA19: -0.021428571 | AB19: 0.16199389 | AD19: 81 | AE19: 66 | AG19: {=AB19*AD19} -> 13.121505 | AH19: {=X19*AE19} -> -2.7176471
A20: 윤태규 | B20: 9 | C20: {=F20/E20} -> 0.29411765 | D20: 20 | E20: 17 | F20: 5 | G20: 5 | H20: 0 | I20: 0 | J20: 0 | K20: 4 | L20: 2 | M20: 3 | N20: 2 | O20: 2 | P20: {=O20/D20} -> 0.1 | Q20: {=(G20*1+H20*2+I20*3+J20*4)/E20} -> 0.29411765 | R20: {=(F20+N20)/D20} -> 0.35 | S20: {=R20+Q20} -> 0.64411765 | T20: {=O20/(D20-(F20+N20))} -> 0.15384615 | U20: {=RANK(R20,$R$4:$R$26)} -> 22 | V20: {=RANK(S20,$S$4:$S$26)} -> 21 | AD20: -18 | AE20: -14 | AG20: {=AB20*AD20} -> 0 | AH20: {=X20*AE20} -> 0
A21: 이동진 | B21: 49 | C21: {=F21/E21} -> 0.225 | D21: 111 | E21: 80 | F21: 18 | G21: 12 | H21: 5 | I21: 1 | J21: 0 | K21: 30 | L21: 27 | M21: 28 | N21: 28 | O21: 24 | P21: {=O21/D21} -> 0.21621622 | Q21: {=(G21*1+H21*2+I21*3+J21*4)/E21} -> 0.3125 | R21: {=(F21+N21)/D21} -> 0.41441441 | S21: {=R21+Q21} -> 0.72691441 | T21: {=O21/(D21-(F21+N21))} -> 0.36923077 | U21: {=RANK(R21,$R$4:$R$26)} -> 20 | V21: {=RANK(S21,$S$4:$S$26)} -> 19 | X21: 0.030555556 | Y21: -0.14548591 | Z21: 0.0625 | AA21: 0.031435691 | AB21: 0.28684873 | AD21: 49 | AE21: 28 | AG21: {=AB21*AD21} -> 14.055588 | AH21: {=X21*AE21} -> 0.85555556
A22: 이철민 | B22: 62 | C22: {=F22/E22} -> 0.4609375 | D22: 150 | E22: 128 | F22: 59 | G22: 44 | H22: 13 | I22: 0 | J22: 2 | K22: 51 | L22: 47 | M22: 26 | N22: 22 | O22: 19 | P22: {=O22/D22} -> 0.12666667 | Q22: {=(G22*1+H22*2+I22*3+J22*4)/E22} -> 0.609375 | R22: {=(F22+N22)/D22} -> 0.54 | S22: {=R22+Q22} -> 1.149375 | T22: {=O22/(D22-(F22+N22))} -> 0.27536232 | U22: {=RANK(R22,$R$4:$R$26)} -> 4 | V22: {=RANK(S22,$S$4:$S$26)} -> 6 | X22: 0.032366071 | Y22: -0.014178404 | Z22: 0.06969246 | AA22: 0.047042254 | AB22: 0.21755682 | AD22: 149 | AE22: 127 | AG22: {=AB22*AD22} -> 32.415966 | AH22: {=X22*AE22} -> 4.1104911
A23: 임지헌 | B23: 40 | C23: {=F23/E23} -> 0.31818182 | D23: 89 | E23: 66 | F23: 21 | G23: 16 | H23: 5 | I23: 0 | J23: 0 | K23: 24 | L23: 17 | M23: 17 | N23: 21 | O23: 22 | P23: {=O23/D23} -> 0.24719101 | Q23: {=(G23*1+H23*2+I23*3+J23*4)/E23} -> 0.39393939 | R23: {=(F23+N23)/D23} -> 0.47191011 | S23: {=R23+Q23} -> 0.86584951 | T23: {=O23/(D23-(F23+N23))} -> 0.46808511 | U23: {=RANK(R23,$R$4:$R$26)} -> 11 | V23: {=RANK(S23,$S$4:$S$26)} -> 16 | X23: 0.0023923445 | Y23: 0.038857678 | Z23: 0.07814992 | AA23: 0.055243446 | AB23: 0.14362728 | AD23: 77 | AE23: 56 | AG23: {=AB23*AD23} -> 11.059301 | AH23: {=X23*AE23} -> 0.13397129
A24: 조태형 | B24: 52 | C24: {=F24/E24} -> 0.32038835 | D24: 131 | E24: 103 | F24: 33 | G24: 21 | H24: 10 | I24: 2 | J24: 0 | K24: 31 | L24: 26 | M24: 18 | N24: 27 | O24: 26 | P24: {=O24/D24} -> 0.19847328 | Q24: {=(G24*1+H24*2+I24*3+J24*4)/E24} -> 0.45631068 | R24: {=(F24+N24)/D24} -> 0.45801527 | S24: {=R24+Q24} -> 0.91432595 | T24: {=O24/(D24-(F24+N24))} -> 0.36619718 | U24: {=RANK(R24,$R$4:$R$26)} -> 13 | V24: {=RANK(S24,$S$4:$S$26)} -> 12 | X24: -0.044996266 | Y24: 0.0049248953 | Z24: -0.06292009 | AA24: -0.0097266683 | AB24: 0.15993998 | AD24: 122 | AE24: 97 | AG24: {=AB24*AD24} -> 19.512678 | AH24: {=X24*AE24} -> -4.3646378
A25: 주혁진 | B25: 1 | C25: {=F25/E25} -> 0 | D25: 2 | E25: 2 | F25: 0 | G25: 0 | H25: 0 | I25: 0 | J25: 0 | K25: 0 | L25: 0 | M25: 0 | N25: 0 | O25: 1 | P25: {=O25/D25} -> 0.5 | Q25: {=(G25*1+H25*2+I25*3+J25*4)/E25} -> 0 | R25: {=(F25+N25)/D25} -> 0 | S25: {=R25+Q25} -> 0 | T25: {=O25/(D25-(F25+N25))} -> 0.5 | U25: {=RANK(R25,$R$4:$R$26)} -> 23 | V25: {=RANK(S25,$S$4:$S$26)} -> 23 | AD25: -32 | AE25: -15 | AG25: {=AB25*AD25} -> 0 | AH25: {=X25*AE25} -> 0
A26: 차현철 | B26: 22 | C26: {=F26/E26} -> 0.22222222 | D26: 56 | E26: 36 | F26: 8 | G26: 8 | H26: 0 | I26: 0 | J26: 0 | K26: 16 | L26: 5 | M26: 6 | N26: 13 | O26: 9 | P26: {=O26/D26} -> 0.16071429 | Q26: {=(G26*1+H26*2+I26*3+J26*4)/E26} -> 0.22222222 | R26: {=(F26+N26)/D26} -> 0.375 | S26: {=R26+Q26} -> 0.59722222 | T26: {=O26/(D26-(F26+N26))} -> 0.25714286 | U26: {=RANK(R26,$R$4:$R$26)} -> 21 | V26: {=RANK(S26,$S$4:$S$26)} -> 22 | X26: 0.13131313 | Y26: -0.026785714 | Z26: 0.13131313 | AA26: 0.1875 | AB26: 0.31881313 | AD26: 19 | AE26: 5 | AG26: {=AB26*AD26} -> 6.0574495 | AH26: {=X26*AE26} -> 0.65656566
A27: 총합 | C27: {=F27/E27} -> 0.39326453 | D27: {=SUM(D4:D26)} -> 2318 | E27: {=SUM(E4:E26)} -> 1841 | F27: {=SUM(F4:F26)} -> 724 | G27: {=SUM(G4:G26)} -> 531 | H27: {=SUM(H4:H26)} -> 148 | I27: {=SUM(I4:I26)} -> 35 | J27: {=SUM(J4:J26)} -> 12 | K27: {=SUM(K4:K26)} -> 735 | ... O27: {=SUM(O4:O26)} -> 355 | P27: {=O27/D27} -> 0.15314927 | Q27: {=(G27*1+H27*2+I27*3+J27*4)/E27} -> 0.53231939 | R27: {=(F27+N27)/D27} -> 0.49611734 | S27: {=R27+Q27} -> 1.0284367 | X27: 0.013634901 | Y27: -0.0335174 | Z27: -0.017680608 | AA27: 0.016117343 | AB27: 0.031738621
A29: 2. 투수 기록
A30: 이름 | B30: 게임수 | C30: 승 | D30: 패 | E30: 세 | F30: 타자 | G30: 타수 | H30: 이닝 | I30: 피안타 | J30: 피홈런 | K30: 볼넷 | L30: 사구 | M30: 탈삼진 | N30: 실점 | O30: 자책점 | P30: 방어율 | Q30: 이닝당 사사구 | R30: 피안타율 | S30: 경기/이닝 | T30: 이닝/K | U30: 수비성공률 | V30: WHIP | X30: 이닝 | Y30: 피안타율 | Z30: 이닝 당 사사구 | AA30: 이닝 당 삼진 | AB30: WHIP
A31: 권강현 | B31: 26 | C31: 4 | D31: 2 | E31: 0 | F31: 280 | G31: 189 | H31: 36.99966 | I31: 71 | J31: 1 | K31: 76 | L31: 13 | M31: 28 | N31: 104 | O31: 73 | P31: {=O31*9/H31} -> 17.75692 | Q31: {=(K31+L31)/H31} -> 2.4054275 | R31: {=I31/H31} -> 1.9189366 | S31: {=H31/B31} -> 1.4230638 | T31: {=M31/H31} -> 0.75676371 | U31: {=O31/N31} -> 0.70192308 | V31: {=(I31+K31+L31)/H31} -> 4.3243641
A32: 김민석 | B32: 9 | C32: 4 | D32: 2 | E32: 0 | F32: 119 | G32: 103 | H32: 25 | I32: 25 | J32: 0 | K32: 13 | L32: 2 | M32: 29 | N32: 24 | O32: 11 | P32: 0 | Q32: - | R32: - | S32: {=H32/B32} -> 2.7777778 | T32: - | V32: - | X32: -29.999967 | Z32: -1.3090921 | AA32: 1.9000021
A33: 김병진 | B33: 24 | C33: 4 | D33: 8 | E33: 0 | F33: 298 | G33: 215 | H33: 35.666633 | I33: 77 | J33: 4 | K33: 69 | L33: 12 | M33: 42 | N33: 130 | O33: 78 | P33: {=O33*9/H33} -> 19.682262 | Q33: {=(K33+L33)/H33} -> 2.2710302 | R33: {=I33/H33} -> 2.1588805 | S33: {=H33/B33} -> 1.4861097 | T33: {=M33/H33} -> 1.1775712 | U33: {=O33/N33} -> 0.6 | V33: {=(I33+K33+L33)/H33} -> 4.4299107 | X33: - | Y33: -0.379581 | Z33: 53 | AA33: 31 | AB33: -0.26239697
A34: 김형준 | B34: 42 | C34: 13 | D34: 8 | E34: 2 | F34: 569 | G34: 467 | H34: 99.999933 | I34: 141 | J34: 2 | K34: 89 | L34: 18 | M34: 132 | N34: 151 | O34: 95 | P34: {=O34*9/H34} -> 8.5500057 | Q34: {=(K34+L34)/H34} -> 1.0700007 | R34: {=I34/H34} -> 1.4100009 | S34: {=H34/B34} -> 2.3809508 | T34: {=M34/H34} -> 1.3200009 | U34: {=O34/N34} -> 0.62913907 | V34: {=(I34+K34+L34)/H34} -> 2.4800017 | X34: - | Y34: -0.82880503 | Z34: 1 | AA34: 128 | AB34: -4.9826849
A35: 남동수 | B35: 8 | C35: 0 | D35: 0 | E35: 0 | F35: 63 | G35: 50 | H35: 9.6666666 | I35: 20 | J35: 0 | K35: 11 | L35: 2 | M35: 10 | N35: 22 | O35: 19 | P35: {=O35*9/H35} -> 17.689655 | Q35: - | R35: - | S35: - | T35: - | V35: - | X35: -3.3333 | Z35: -1.9628732 | AA35: 0.90000899
A36: 류동현 | B36: 26 | C36: 3 | D36: 7 | E36: 0 | F36: 275 | G36: 196 | H36: 33.333259 | I36: 80 | J36: 2 | K36: 66 | L36: 13 | M36: 40 | N36: 121 | O36: 92 | P36: {=O36*9/H36} -> 24.840055 | Q36: {=(K36+L36)/H36} -> 2.3700053 | R36: {=I36/H36} -> 2.4000053 | S36: {=H36/B36} -> 1.2820484 | T36: {=M36/H36} -> 1.2000027 | U36: {=O36/N36} -> 0.76033058 | V36: {=(I36+K36+L36)/H36} -> 4.7700106 | X36: 6.0002593 | Y36: 0.97315866 | Z36: 1.4919458 | AA36: 0.16665946 | AB36: 2.4651044
A37: 박영준 | B37: 12 | C37: 2 | D37: 3 | E37: 0 | F37: 178 | G37: 128 | H37: 23.666633 | I37: 66 | J37: 1 | K37: 36 | L37: 10 | M37: 27 | N37: 78 | O37: 63 | P37: {=O37*9/H37} -> 23.957781 | Q37: {=(K37+L37)/H37} -> 1.9436648 | R37: {=I37/H37} -> 2.7887364 | S37: {=H37/B37} -> 1.9722194 | T37: {=M37/H37} -> 1.1408467 | U37: {=O37/N37} -> 0.80769231 | V37: {=(I37+K37+L37)/H37} -> 4.7324012
A38: 이동진 | B38: 5 | C38: 0 | D38: 2 | E38: 0 | F38: 54 | G38: 43 | H38: 5 | I38: 26 | J38: 2 | K38: 8 | L38: 3 | M38: 6 | N38: 31 | O38: 23 | P38: {=O38*9/H38} -> 41.4 | Q38: - | R38: - | S38: - | T38: - | U38: {=O38/N38} -> 0.74193548 | V38: - | X38: 4 | Z38: 1.2 | AA38: 1.25
A39: 이철민 | B39: 0 | C39: 0 | D39: 0 | E39: 0 | F39: 0 | G39: 0 | H39: 0 | I39: 0 | J39: 0 | K39: 0 | L39: 0 | M39: 0 | N39: 0 | O39: 0
A40: 임지헌 | B40: 8 | C40: 2 | D40: 2 | E40: 1 | F40: 102 | G40: 55 | H40: 13.666633 | I40: 16 | J40: 1 | K40: 45 | L40: 1 | M40: 13 | N40: 36 | O40: 21 | P40: {=O40*9/H40} -> 13.829302 | Q40: {=(K40+L40)/H40} -> 3.3658619 | R40: {=I40/H40} -> 1.1707346 | S40: {=H40/B40} -> 1.7083292 | T40: {=M40/H40} -> 0.95122183 | U40: {=O40/N40} -> 0.58333333 | V40: {=(I40+K40+L40)/H40} -> 4.5365964 | X40: -5.3333667 | Y40: -0.98716017 | Z40: 1.2079671 | AA40: 1.4999906 | AB40: 0.22080696
A41: 조태형 | B41: 38 | C41: 8 | D41: 11 | E41: 3 | F41: 550 | G41: 397 | H41: 81.666633 | I41: 133 | J41: 1 | K41: 123 | L41: 25 | M41: 131 | N41: 183 | O41: 130 | P41: {=O41*9/H41} -> 14.326537 | Q41: {=(K41+L41)/H41} -> 1.8122456 | R41: {=I41/H41} -> 1.6285721 | S41: {=H41/B41} -> 2.1491219 | T41: {=M41/H41} -> 1.6040823 | U41: {=O41/N41} -> 0.71038251 | V41: {=(I41+K41+L41)/H41} -> 3.4408177 | X41: - | Y41: - | Z41: - | AA41: - | AB41: -
...

Sheet 시즌별 정리
A1: ◎ 라스칼 통산 성적
A2: 1. 리그별 타율
A3: 이름 | B3: 22년 | C3: 23년 | F3: 24년 | J3: 25년
B4: 上샘프 | C4: 下드림즈 | D4: 上코모도 | E4: 上디비전 | F4: 下서구 | G4: 下코모도 | H4: 上코모도 (6부-B) | I4: 上디비전 | J4: 下코모도 (6부C+A) | K4: 上코모도 (6부-BB) | L4: 디비전
A5: 권강현 | F5: 0.25 | I5: 0.090909091 | J5: 0.54545455 | K5: 0.33333333 | N5: 규정 타석 미달
A6: 권혁진 | B6: 0 | C6: 0.5 | D6: 0 | F6: 0.25 | I6: 0 | J6: 0.11111111 | N6: 타율 0.300 미만
A7: 김기태 | B7: 0.75 | C7: 0.417 | D7: 0.474 | E7: 0.44444444 | F7: 0.61111111 | G7: 0.46666667 | H7: 0.6 | I7: 0.6 | J7: 0.61904762 | K7: 0.44444444 | N7: 타율 0.500 미만
A8: 김민석 | F8: 0 | N8: 타율 0.500 이상
A9: 김범희 | B9: 0.45 | C9: 0.455 | D9: 0.25 | E9: 0.33333333 | F9: 0 | G9: 0.5 | H9: 0.16666667 | I9: 0.5 | J9: 0.125 | K9: 0.61538462 | N9: 타율 0.700 이상
A10: 김병진 | B10: 0.333 | C10: 0.091 | D10: 0.2 | F10: 0.25 | H10: 0.5 | I10: 0.25 | J10: 0.41666667
A11: 김상훈 | J11: 0.22222222
A12: 김재영 | B12: 0.357 | C12: 0.75 | D12: 0.542 | E12: 0.58333333 | F12: 0.5 | G12: 0.7 | H12: 0.5483871 | I12: 0.5 | J12: 0.54545455 | K12: 0.66666667
A13: 김태양 | B13: 0.364 | C13: 0.231 | D13: 0.333 | F13: 0.25 | G13: 0.28571429 | H13: 0.25 | I13: 0.3 | J13: 0.45833333 | K13: 0.375
A14: 김현철 | D14: 0.333 | E14: 0 | F14: 0.66666667 | G14: 0 | H14: 0.33333333 | I14: 0.28571429 | J14: 0.44444444 | K14: 0.28571429
A15: 김형준 | B15: 0.25 | C15: 0.462 | D15: 0.435 | E15: 0.83333333 | F15: 0.375 | G15: 0.53333333 | H15: 0.51851852 | J15: 0.55 | K15: 0.38888889
A16: 남동수 | C16: 0 | D16: 0.222 | F16: 0.11111111 | G16: 0.14285714 | H16: 0.33333333 | I16: 0.33333333 | J16: 0.21428571 | K16: 0.57142857
A17: 류동현 | B17: 0.429 | C17: 0.2 | E17: 0.66666667 | F17: 0.46153846 | G17: 0.46153846 | H17: 0.090909091 | I17: 0.28571429 | J17: 0.29411765
A18: 박영준 | D18: 0 | E18: 0.42857143 | F18: 0.41666667 | G18: 0.375 | H18: 0.31818182 | I18: 0.625 | J18: 0.30769231 | K18: 0.6
A19: 박재현 | C19: 0.429 | D19: 0.611 | E19: 0.4 | F19: 0.44444444 | G19: 0.25 | H19: 0.33333333 | I19: 0.41176471 | J19: 0.25 | K19: 0.42857143
A20: 백정철 | B20: 0.429 | C20: 0.5 | D20: 0.286 | E20: 0.5 | G20: 0.5 | H20: 0.3 | I20: 0.4 | J20: 0.35294118 | K20: 0.30769231
A21: 윤태규 | J21: 0.42857143 | K21: 0.4
A22: 이동진 | B22: 0.333 | C22: 0.143 | D22: 0.143 | E22: 0 | F22: 0.5 | H22: 0 | J22: 0.5
A23: 이철민 | B23: 0.56 | C23: 0.545 | D23: 0.304 | F23: 0.45454545 | G23: 0.46666667 | H23: 0.58333333 | I23: 0.75
A24: 임지헌 | B24: 0.25 | C24: 0.167 | D24: 0.571 | F24: 0.4 | G24: 0.25 | H24: 0.18181818 | I24: 0.57142857 | J24: 0.28571429
A25: 조태형 | B25: 0.5 | C25: 0.2 | D25: 0.4 | E25: 0.2 | F25: 0.22222222 | G25: 0.36363636 | H25: 0.28571429 | I25: 0.375 | J25: 0.51612903 | K25: 0.3
A26: 주혁진 | K26: 0.3
A27: 차현철 | D27: 0 | E27: 0.25 | F27: 0 | G27: 0 | H27: 0.5 | I27: 0.33333333 | J27: 0.24 | K27: 0.36363636
A28: 총합 | B28: 0.43283582 | C28: 0.34285714 | D28: 0.35748792 | E28: 0.37 | F28: 0.38607595 | G28: 0.38732394 | H28: 0.42439024 | I28: 0.37341772 | J28: 0.40066225

Sheet 통산 성적(~'24) (김희제 포함)
A1: ◎ 라스칼 통산 성적
A2: 1. 타자 기록
A3: 이름 | B3: 게임수 | C3: 타율 | D3: 타석 | E3: 타수 | F3: 안타 | G3: 1루타 | H3: 2루타 | I3: 3루타 | J3: 홈런 | K3: 득점 | L3: 타점 | M3: 도루 | N3: 사사구 | O3: 삼진 | P3: 삼진률 | Q3: 장타율 | R3: 출루율 | S3: OPS | T3: 아웃 比 삼진률 | U3: 출루율 등수 | V3: OPS 등수
A4: 김기태 | B4: 52 | C4: {=F4/E4} -> 0.56097561 | D4: 150 | E4: 123 | F4: 69 | G4: 50 | H4: 14 | I4: 4 | J4: 1 | K4: 57 | L4: 62 | M4: 39 | N4: 25 | O4: 9 | P4: {=O4/D4} -> 0.06 | Q4: {=(G4*1+H4*2+I4*3+J4*4)/E4} -> 0.76422764 | R4: {=(F4+N4)/D4} -> 0.62666667 | S4: {=R4+Q4} -> 1.3908943 | T4: {=O4/(D4-(F4+N4))} -> 0.16071429 | U4: {=RANK(R4,$R$4:$R$24)} -> 1 | V4: {=RANK(S4,$S$4:$S$24)} -> 1
A5: 김재영 | B5: 54 | C5: {=F5/E5} -> 0.53191489 | D5: 168 | E5: 141 | F5: 75 | G5: 54 | H5: 12 | I5: 8 | J5: 1 | K5: 69 | L5: 50 | M5: 79 | N5: 22 | O5: 12 | P5: {=O5/D5} -> 0.071428571 | Q5: {=(G5*1+H5*2+I5*3+J5*4)/E5} -> 0.75177305 | R5: {=(F5+N5)/D5} -> 0.57738095 | S5: {=R5+Q5} -> 1.329154 | T5: {=O5/(D5-(F5+N5))} -> 0.16901408 | U5: {=RANK(R5,$R$4:$R$24)} -> 2 | V5: {=RANK(S5,$S$4:$S$24)} -> 3
A6: 김형준 | B6: 47 | C6: {=F6/E6} -> 0.5 | D6: 125 | E6: 104 | F6: 52 | G6: 29 | H6: 20 | I6: 2 | J6: 1 | K6: 40 | L6: 42 | M6: 19 | N6: 20 | O6: 5 | P6: {=O6/D6} -> 0.04 | Q6: {=(G6*1+H6*2+I6*3+J6*4)/E6} -> 0.75961538 | R6: {=(F6+N6)/D6} -> 0.576 | S6: {=R6+Q6} -> 1.3356154 | T6: {=O6/(D6-(F6+N6))} -> 0.094339623 | U6: {=RANK(R6,$R$4:$R$24)} -> 3 | V6: {=RANK(S6,$S$4:$S$24)} -> 2
A7: 박재현 | B7: 41 | C7: {=F7/E7} -> 0.42857143 | D7: 90 | E7: 77 | F7: 33 | G7: 26 | H7: 5 | I7: 1 | J7: 1 | K7: 23 | L7: 17 | M7: 12 | N7: 11 | O7: 13 | P7: {=O7/D7} -> 0.14444444 | Q7: {=(G7*1+H7*2+I7*3+J7*4)/E7} -> 0.55844156 | R7: {=(F7+N7)/D7} -> 0.48888889 | S7: {=R7+Q7} -> 1.0473304 | T7: {=O7/(D7-(F7+N7))} -> 0.2826087 | U7: {=RANK(R7,$R$4:$R$24)} -> 8 | V7: {=RANK(S7,$S$4:$S$24)} -> 7
A8: 이철민 | B8: 54 | C8: {=F8/E8} -> 0.47863248 | D8: 134 | E8: 117 | F8: 56 | G8: 41 | H8: 13 | I8: 0 | J8: 2 | K8: 47 | L8: 43 | M8: 20 | N8: 17 | O8: 14 | P8: {=O8/D8} -> 0.10447761 | Q8: {=(G8*1+H8*2+I8*3+J8*4)/E8} -> 0.64102564 | R8: {=(F8+N8)/D8} -> 0.54477612 | S8: {=R8+Q8} -> 1.1858018 | T8: {=O8/(D8-(F8+N8))} -> 0.2295082 | U8: {=RANK(R8,$R$4:$R$24)} -> 4 | V8: {=RANK(S8,$S$4:$S$24)} -> 4
A9: 류동현 | B9: 37 | C9: {=F9/E9} -> 0.35 | D9: 68 | E9: 60 | F9: 21 | G9: 16 | H9: 5 | I9: 0 | J9: 0 | K9: 17 | L9: 22 | M9: 13 | N9: 7 | O9: 13 | P9: {=O9/D9} -> 0.19117647 | Q9: {=(G9*1+H9*2+I9*3+J9*4)/E9} -> 0.43333333 | R9: {=(F9+N9)/D9} -> 0.41176471 | S9: {=R9+Q9} -> 0.84509804 | T9: {=O9/(D9-(F9+N9))} -> 0.325 | U9: {=RANK(R9,$R$4:$R$24)} -> 13 | V9: {=RANK(S9,$S$4:$S$24)} -> 11
A10: 박영준 | B10: 28 | C10: {=F10/E10} -> 0.38235294 | D10: 88 | E10: 68 | F10: 26 | G10: 19 | H10: 3 | I10: 4 | J10: 0 | K10: 27 | L10: 14 | M10: 25 | N10: 19 | O10: 13 | P10: {=O10/D10} -> 0.14772727 | Q10: {=(G10*1+H10*2+I10*3+J10*4)/E10} -> 0.54411765 | R10: {=(F10+N10)/D10} -> 0.51136364 | S10: {=R10+Q10} -> 1.0554813 | T10: {=O10/(D10-(F10+N10))} -> 0.30232558 | U10: {=RANK(R10,$R$4:$R$24)} -> 6 | V10: {=RANK(S10,$S$4:$S$24)} -> 6
A11: 김범희 | B11: 44 | C11: {=F11/E11} -> 0.36470588 | D11: 112 | E11: 85 | F11: 31 | G11: 20 | H11: 7 | I11: 3 | J11: 1 | K11: 35 | L11: 33 | M11: 19 | N11: 26 | O11: 23 | P11: {=O11/D11} -> 0.20535714 | Q11: {=(G11*1+H11*2+I11*3+J11*4)/E11} -> 0.55294118 | R11: {=(F11+N11)/D11} -> 0.50892857 | S11: {=R11+Q11} -> 1.0618697 | T11: {=O11/(D11-(F11+N11))} -> 0.41818182 | U11: {=RANK(R11,$R$4:$R$24)} -> 7 | V11: {=RANK(S11,$S$4:$S$24)} -> 5
A12: 조태형 | B12: 44 | C12: {=F12/E12} -> 0.34042553 | D12: 115 | E12: 94 | F12: 32 | G12: 20 | H12: 10 | I12: 2 | J12: 0 | K12: 28 | L12: 25 | M12: 17 | N12: 20 | O12: 20 | P12: {=O12/D12} -> 0.17391304 | Q12: {=(G12*1+H12*2+I12*3+J12*4)/E12} -> 0.4893617 | R12: {=(F12+N12)/D12} -> 0.45217391 | S12: {=R12+Q12} -> 0.94153562 | T12: {=O12/(D12-(F12+N12))} -> 0.31746032 | U12: {=RANK(R12,$R$4:$R$24)} -> 10 | V12: {=RANK(S12,$S$4:$S$24)} -> 8
A13: 백정철 | B13: 31 | C13: {=F13/E13} -> 0.35384615 | D13: 80 | E13: 65 | F13: 23 | G13: 22 | H13: 0 | I13: 0 | J13: 1 | K13: 20 | L13: 22 | M13: 7 | N13: 13 | O13: 10 | P13: {=O13/D13} -> 0.125 | Q13: {=(G13*1+H13*2+I13*3+J13*4)/E13} -> 0.4 | R13: {=(F13+N13)/D13} -> 0.45 | S13: {=R13+Q13} -> 0.85 | T13: {=O13/(D13-(F13+N13))} -> 0.22727273 | U13: {=RANK(R13,$R$4:$R$24)} -> 11 | V13: {=RANK(S13,$S$4:$S$24)} -> 10
A14: 임지헌 | B14: 34 | C14: {=F14/E14} -> 0.33928571 | D14: 74 | E14: 56 | F14: 19 | G14: 15 | H14: 4 | I14: 0 | J14: 0 | K14: 22 | L14: 17 | M14: 16 | N14: 16 | O14: 18 | P14: {=O14/D14} -> 0.24324324 | Q14: {=(G14*1+H14*2+I14*3+J14*4)/E14} -> 0.41071429 | R14: {=(F14+N14)/D14} -> 0.47297297 | S14: {=R14+Q14} -> 0.88368726 | T14: {=O14/(D14-(F14+N14))} -> 0.46153846 | U14: {=RANK(R14,$R$4:$R$24)} -> 9 | V14: {=RANK(S14,$S$4:$S$24)} -> 9
A15: 김현철 | B15: 20 | C15: {=F15/E15} -> 0.30769231 | D15: 41 | E15: 26 | F15: 8 | G15: 7 | H15: 1 | I15: 0 | J15: 0 | K15: 16 | L15: 5 | M15: 11 | N15: 8 | O15: 2 | P15: {=O15/D15} -> 0.048780488 | Q15: {=(G15*1+H15*2+I15*3+J15*4)/E15} -> 0.34615385 | R15: {=(F15+N15)/D15} -> 0.3902439 | S15: {=R15+Q15} -> 0.73639775 | T15: {=O15/(D15-(F15+N15))} -> 0.08 | U15: {=RANK(R15,$R$4:$R$24)} -> 16 | V15: {=RANK(S15,$S$4:$S$24)} -> 13
... A24: 김민석 | B24: 4 | C24: {=F24/E24} -> 0 | D24: 11 | E24: 7 | F24: 0 | G24: 0 | H24: 0 | I24: 0 | J24: 0 | K24: 4 | L24: 6 | M24: 1 | N24: 4 | O24: 2 | P24: {=O24/D24} -> 0.18181818 | Q24: {=(G24*1+H24*2+I24*3+J24*4)/E24} -> 0 | R24: {=(F24+N24)/D24} -> 0.36363636 | S24: {=R24+Q24} -> 0.36363636 | T24: {=O24/(D24-(F24+N24))} -> 0.28571429 | U24: {=RANK(R24,$R$4:$R$24)} -> 18 | V24: {=RANK(S24,$S$4:$S$24)} -> 21
A25: 총합 | C25: {=F25/E25} -> 0.38318452 | D25: {=SUM(D4:D24)} -> 1688 | E25: {=SUM(E4:E24)} -> 1344 | F25: {=SUM(F4:F24)} -> 515 | G25: {=SUM(G4:G24)} -> 377 | H25: {=SUM(H4:H24)} -> 104 | I25: {=SUM(I4:I24)} -> 26 | J25: {=SUM(J4:J24)} -> 8 | K25: {=SUM(K4:K24)} -> 515 | ... O25: {=SUM(O4:O24)} -> 282 | P25: {=O25/D25} -> 0.16706161 | Q25: {=(G25*1+H25*2+I25*3+J25*4)/E25} -> 0.5171131 | R25: {=(F25+N25)/D25} -> 0.48992891 | S25: {=R25+Q25} -> 1.007042
A27: 2. 투수 기록
A28: 이름 | B28: 게임수 | C28: 승 | D28: 패 | E28: 세 | F28: 타자 | G28: 타수 | H28: 이닝 | I28: 피안타 | J28: 피홈런 | K28: 볼넷 | L28: 사구 | M28: 탈삼진 | N28: 실점 | O28: 자책점 | P28: 방어율 | Q28: 제구 | R28: 피안타율 | S28: 경기/이닝 | T28: 이닝/K | U28: 수비성공률 | V28: WHIP
A29: 권강현 | B29: 15 | C29: 1 | D29: 2 | E29: 0 | F29: 105 | G29: 52 | H29: 8.99966 | I29: 19 | J29: 0 | K29: 48 | L29: 4 | M29: 5 | N29: 56 | O29: 36 | P29: {=O29*9/H29} -> 36.00136 | Q29: {=(K29+L29)/H29} -> 5.7779961 | R29: {=I29/H29} -> 2.1111909 | S29: {=H29/B29} -> 0.59997733 | T29: {=M29/H29} -> 0.55557654 | U29: {=O29/N29} -> 0.64285714 | V29: {=(I29+K29+L29)/H29} -> 7.8891869
A30: 김민석 | B30: 1 | C30: 0 | D30: 0 | E30: 0 | F30: 1 | G30: 0 | H30: 0 | I30: 0 | J30: 0 | K30: 1 | L30: 0 | M30: 0 | N30: 0 | O30: 0 | P30: 0 | Q30: - | R30: - | S30: {=H30/B30} -> 0 | T30: - | U30: - | V30: -
A31: 김병진 | B31: 12 | C31: 2 | D31: 2 | E31: 0 | F31: 128 | G31: 96 | H31: 13.999966 | I31: 37 | J31: 3 | K31: 27 | L31: 5 | M31: 13 | N31: 55 | O31: 33 | P31: {=O31*9/H31} -> 21.214337 | Q31: {=(K31+L31)/H31} -> 2.2857198 | R31: {=I31/H31} -> 2.6428635 | S31: {=H31/B31} -> 1.1666639 | T31: {=M31/H31} -> 0.92857366 | U31: {=O31/N31} -> 0.6 | V31: {=(I31+K31+L31)/H31} -> 4.9285833
A32: 김형준 | B32: 35 | C32: 11 | D32: 7 | E32: 2 | F32: 475 | G32: 403 | H32: 88.333267 | I32: 110 | J32: 1 | K32: 65 | L32: 14 | M32: 121 | N32: 115 | O32: 69 | P32: {=O32*9/H32} -> 7.030194 | Q32: {=(K32+L32)/H32} -> 0.8943403 | R32: {=I32/H32} -> 1.245284 | S32: {=H32/B32} -> 2.5238076 | T32: {=M32/H32} -> 1.3698124 | U32: {=O32/N32} -> 0.6 | V32: {=(I32+K32+L32)/H32} -> 2.1396243
A33: 류동현 | B33: 19 | C33: 2 | D33: 5 | E33: 0 | F33: 207 | G33: 143 | H33: 25.999927 | I33: 58 | J33: 2 | K33: 61 | L33: 4 | M33: 27 | N33: 87 | O33: 68 | P33: {=O33*9/H33} -> 23.538528 | Q33: {=(K33+L33)/H33} -> 2.5000071 | R33: {=I33/H33} -> 2.2307755 | S33: {=H33/B33} -> 1.3684172 | T33: {=M33/H33} -> 1.0384645 | U33: {=O33/N33} -> 0.7816092 | V33: {=(I33+K33+L33)/H33} -> 4.7307826
A34: 박영준 | B34: 11 | C34: 2 | D34: 3 | E34: 0 | F34: 173 | G34: 127 | H34: 23.333299 | I34: 66 | J34: 1 | K34: 33 | L34: 9 | M34: 27 | N34: 74 | O34: 62 | P34: 0 | Q34: {=(K34+L34)/H34} -> 1.8000026 | R34: {=I34/H34} -> 2.8285756 | S34: {=H34/B34} -> 2.121209 | T34: {=M34/H34} -> 1.1571445 | U34: - | V34: {=(I34+K34+L34)/H34} -> 4.6285782
A35: 임지헌 | B35: 8 | C35: 2 | D35: 2 | E35: 1 | F35: 102 | G35: 55 | H35: 13.666633 | I35: 16 | J35: 1 | K35: 45 | L35: 1 | M35: 13 | N35: 36 | O35: 21 | P35: {=O35*9/H35} -> 13.829302 | Q35: {=(K35+L35)/H35} -> 3.3658619 | R35: {=I35/H35} -> 1.1707346 | S35: {=H35/B35} -> 1.7083292 | T35: {=M35/H35} -> 0.95122183 | U35: {=O35/N35} -> 0.58333333 | V35: {=(I35+K35+L35)/H35} -> 4.5365964
A36: 조태형 | B36: 38 | C36: 8 | D36: 11 | E36: 3 | F36: 550 | G36: 397 | H36: 81.666633 | I36: 133 | J36: 1 | K36: 123 | L36: 25 | M36: 131 | N36: 183 | O36: 130 | P36: {=O36*9/H36} -> 14.326537 | Q36: {=(K36+L36)/H36} -> 1.8122456 | R36: {=I36/H36} -> 1.6285721 | S36: {=H36/B36} -> 2.1491219 | T36: {=M36/H36} -> 1.6040823 | U36: {=O36/N36} -> 0.71038251 | V36: {=(I36+K36+L36)/H36} -> 3.4408177
A37: 총합 | B37: {=SUM(B29:B36)} -> 139 | C37: {=SUM(C29:C36)} -> 28 | D37: {=SUM(D29:D36)} -> 32 | E37: {=SUM(E29:E36)} -> 6 | F37: {=SUM(F29:F36)} -> 1741 | G37: {=SUM(G29:G36)} -> 1273 | H37: {=SUM(H29:H36)} -> 255.99939 | I37: {=SUM(I29:I36)} -> 439 | ... O37: {=SUM(O29:O36)} -> 419 | P37: {=O37*9/H37} -> 14.730504 | Q37: {=(K37+L37)/H37} -> 1.8164106 | R37: {=I37/H37} -> 1.7148479 | S37: {=H37/B37} -> 1.8417222 | T37: {=M37/H37} -> 1.3164094 | U37: {=O37/N37} -> 0.69141914 | V37: {=(I37+K37+L37)/H37} -> 3.5312585

Sheet 22년 샘프리그(22')
A1: ◎ 22년 상반기 샘프리그
A2: 1. 타자 기록
A3: 이름 | B3: 게임수 | C3: 타율 | D3: 타석 | E3: 타수 | F3: 안타 | G3: 1루타 | H3: 2루타 | I3: 3루타 | J3: 홈런 | K3: 득점 | L3: 타점 | M3: 도루 | N3: 사사구 | O3: 삼진 | P3: 장타율 | Q3: 출루율 | R3: OPS
A4: 권강현 | B4: 2 | C4: 0 | D4: 1 | E4: 1 | F4: 0 | G4: 0 | H4: 0 | I4: 0 | J4: 0 | K4: 0 | L4: 0 | M4: 0 | N4: 0 | O4: 1 | P4: {=(G4*1+H4*2+I4*3+J4*4)/E4} -> 0 | Q4: 0 | R4: {=Q4+P4} -> 0
A5: 권혁진 | B5: 6 | C5: 0 | D5: 11 | E5: 3 | F5: 0 | G5: 0 | H5: 0 | I5: 0 | J5: 0 | K5: 2 | L5: 1 | M5: 2 | N5: 8 | O5: 3 | P5: {=(G5*1+H5*2+I5*3+J5*4)/E5} -> 0 | Q5: 0.727 | R5: {=Q5+P5} -> 0.727
A6: 김기태 | B6: 9 | C6: 0.75 | D6: 28 | E6: 20 | F6: 15 | G6: 10 | H6: 4 | I6: 1 | J6: 0 | K6: 14 | L6: 11 | M6: 11 | N6: 8 | O6: 1 | P6: {=(G6*1+H6*2+I6*3+J6*4)/E6} -> 1.05 | Q6: 0.821 | R6: {=Q6+P6} -> 1.871
A7: 김민석 | B7: 0 | D7: 0 | E7: 0 | F7: 0 | G7: 0 | H7: 0 | I7: 0 | J7: 0 | K7: 0 | L7: 0 | M7: 0 | N7: 0 | O7: 0 | P7: 0 | Q7: 0 | R7: {=Q7+P7} -> 0
A8: 김범희 | B8: 9 | C8: 0.45 | D8: 22 | E8: 20 | F8: 9 | G8: 6 | H8: 3 | I8: 0 | J8: 0 | K8: 8 | L8: 9 | M8: 6 | N8: 2 | O8: 4 | P8: {=(G8*1+H8*2+I8*3+J8*4)/E8} -> 0.6 | Q8: 0.5 | R8: {=Q8+P8} -> 1.1
A9: 김병진 | B9: 5 | C9: 0.333 | D9: 13 | E9: 12 | F9: 4 | G9: 3 | H9: 1 | I9: 0 | J9: 0 | K9: 2 | L9: 1 | M9: 2 | N9: 1 | O9: 4 | P9: {=(G9*1+H9*2+I9*3+J9*4)/E9} -> 0.41666667 | Q9: 0.385 | R9: {=Q9+P9} -> 0.80166667
A10: 김재영 | B10: 9 | C10: 0.357 | D10: 31 | E10: 28 | F10: 10 | G10: 6 | H10: 3 | I10: 1 | J10: 0 | K10: 7 | L10: 8 | M10: 5 | N10: 3 | O10: 5 | P10: {=(G10*1+H10*2+I10*3+J10*4)/E10} -> 0.53571429 | Q10: 0.419 | R10: {=Q10+P10} -> 0.95471429
A11: 김태양 | B11: 5 | C11: 0.364 | D11: 13 | E11: 11 | F11: 4 | G11: 4 | H11: 0 | I11: 0 | J11: 0 | K11: 4 | L11: 5 | M11: 3 | N11: 2 | O11: 4 | P11: {=(G11*1+H11*2+I11*3+J11*4)/E11} -> 0.36363636 | Q11: 0.462 | R11: {=Q11+P11} -> 0.82563636
A12: 김현철 | B12: 0 | D12: 0 | E12: 0 | F12: 0 | G12: 0 | H12: 0 | I12: 0 | J12: 0 | K12: 0 | L12: 0 | M12: 0 | N12: 0 | O12: 0 | P12: 0 | Q12: 0 | R12: {=Q12+P12} -> 0
A13: 김형준 | B13: 4 | C13: 0.25 | D13: 6 | E13: 4 | F13: 1 | G13: 0 | H13: 0 | I13: 0 | J13: 1 | K13: 2 | L13: 3 | M13: 0 | N13: 2 | O13: 1 | P13: {=(G13*1+H13*2+I13*3+J13*4)/E13} -> 1 | Q13: 0.5 | R13: {=Q13+P13} -> 1.5
A14: 김희제 | B14: 7 | C14: 0.286 | D14: 17 | E14: 14 | F14: 4 | G14: 3 | H14: 0 | I14: 1 | J14: 0 | K14: 6 | L14: 1 | M14: 3 | N14: 3 | O14: 5 | P14: {=(G14*1+H14*2+I14*3+J14*4)/E14} -> 0.42857143 | Q14: 0.412 | R14: {=Q14+P14} -> 0.84057143
A15: 남동수 | B15: 0 | D15: 0 | E15: 0 | F15: 0 | G15: 0 | H15: 0 | I15: 0 | J15: 0 | K15: 0 | L15: 0 | M15: 0 | N15: 0 | O15: 0 | P15: 0 | Q15: 0 | R15: {=Q15+P15} -> 0
A16: 류동현 | B16: 6 | C16: 0.429 | D16: 9 | E16: 7 | F16: 3 | G16: 2 | H16: 1 | I16: 0 | J16: 0 | K16: 1 | L16: 3 | M16: 2 | N16: 2 | O16: 1 | P16: {=(G16*1+H16*2+I16*3+J16*4)/E16} -> 0.57142857 | Q16: 0.556 | R16: {=Q16+P16} -> 1.1274286
A17: 박영준 | B17: 0 | D17: 0 | E17: 0 | F17: 0 | G17: 0 | H17: 0 | I17: 0 | J17: 0 | K17: 0 | L17: 0 | M17: 0 | N17: 0 | O17: 0 | P17: 0 | Q17: 0 | R17: {=Q17+P17} -> 0
A18: 박재현 | B18: 1 | C18: 0 | D18: 1 | E18: 1 | F18: 0 | G18: 0 | H18: 0 | I18: 0 | J18: 0 | K18: 0 | L18: 0 | M18: 0 | N18: 0 | O18: 1 | P18: {=(G18*1+H18*2+I18*3+J18*4)/E18} -> 0 | Q18: 0 | R18: {=Q18+P18} -> 0
A19: 백정철 | B19: 7 | C19: 0.429 | D19: 18 | E19: 14 | F19: 6 | G19: 6 | H19: 0 | I19: 0 | J19: 0 | K19: 7 | L19: 7 | M19: 3 | N19: 4 | O19: 2 | P19: {=(G19*1+H19*2+I19*3+J19*4)/E19} -> 0.42857143 | Q19: 0.556 | R19: {=Q19+P19} -> 0.98457143
A20: 이동진 | B20: 8 | C20: 0.333 | D20: 18 | E20: 15 | F20: 5 | G20: 3 | H20: 2 | I20: 0 | J20: 0 | K20: 4 | L20: 8 | M20: 6 | N20: 3 | O20: 2 | P20: {=(G20*1+H20*2+I20*3+J20*4)/E20} -> 0.46666667 | Q20: 0.444 | R20: {=Q20+P20} -> 0.91066667
A21: 이철민 | B21: 9 | C21: 0.56 | D21: 27 | E21: 25 | F21: 14 | G21: 13 | H21: 1 | I21: 0 | J21: 0 | K21: 5 | L21: 9 | M21: 4 | N21: 2 | O21: 2 | P21: {=(G21*1+H21*2+I21*3+J21*4)/E21} -> 0.6 | Q21: 0.593 | R21: {=Q21+P21} -> 1.193
A22: 임지헌 | B22: 3 | C22: 0.25 | D22: 6 | E22: 4 | F22: 1 | G22: 1 | H22: 0 | I22: 0 | J22: 0 | K22: 5 | L22: 1 | M22: 4 | N22: 2 | O22: 1 | P22: {=(G22*1+H22*2+I22*3+J22*4)/E22} -> 0.25 | Q22: 0.5 | R22: {=Q22+P22} -> 0.75
A23: 조태형 | B23: 9 | C23: 0.5 | D23: 24 | E23: 22 | F23: 11 | G23: 6 | H23: 4 | I23: 1 | J23: 0 | K23: 9 | L23: 6 | M23: 3 | N23: 2 | O23: 3 | P23: {=(G23*1+H23*2+I23*3+J23*4)/E23} -> 0.77272727 | Q23: 0.542 | R23: {=Q23+P23} -> 1.3147273
A24: 차현철 | B24: 0 | D24: 0 | E24: 0 | F24: 0 | G24: 0 | H24: 0 | I24: 0 | J24: 0 | K24: 0 | L24: 0 | M24: 0 | N24: 0 | O24: 0 | P24: 0 | Q24: 0 | R24: {=Q24+P24} -> 0
A25: 총합 | C25: {=F25/E25} -> 0.43283582 | D25: {=SUM(D4:D24)} -> 245 | E25: {=SUM(E4:E24)} -> 201 | F25: {=SUM(F4:F24)} -> 87 | G25: {=SUM(G4:G24)} -> 63 | H25: {=SUM(H4:H24)} -> 19 | I25: {=SUM(I4:I24)} -> 4 | J25: {=SUM(J4:J24)} -> 1 | K25: {=SUM(K4:K23)} -> 76 | L25: {=SUM(L4:L23)} -> 73 | M25: {=SUM(M4:M23)} -> 54 | N25: {=SUM(N4:N23)} -> 44 | O25: {=SUM(O4:O23)} -> 40
A27: 2. 투수 기록
A28: 이름 | B28: 게임수 | C28: 승 | D28: 패 | E28: 세 | F28: 타자 | G28: 타수 | H28: 이닝 | I28: 피안타 | J28: 피홈런 | K28: 볼넷 | L28: 사구 | M28: 탈삼진 | N28: 실점 | O28: 자책점 | P28: 방어율
A29: 김민석 | B29: 1 | C29: 0 | D29: 0 | E29: 0 | F29: 1 | G29: 0 | H29: 0 | I29: 0 | J29: 0 | K29: 1 | L29: 0 | M29: 0 | N29: 0 | O29: 0 | P29: 0
A30: 권강현 | B30: 2 | C30: 0 | D30: 0 | E30: 0 | F30: 2 | G30: 0 | H30: 0 | I30: 0 | J30: 0 | K30: 2 | L30: 0 | M30: 0 | N30: 1 | O30: 0 | P30: 0
A31: 김형준 | B31: 4 | C31: 2 | D31: 0 | E31: 0 | F31: 36 | G31: 30 | H31: 7.1 | I31: 10 | J31: 0 | K31: 6 | L31: 0 | M31: 5 | N31: 7 | O31: 3 | P31: {=O31*9/H31} -> 3.8028169
A32: 조태형 | B32: 9 | C32: 2 | D32: 4 | E32: 1 | F32: 180 | G32: 126 | H32: 26 | I32: 40 | J32: 0 | K32: 46 | L32: 7 | M32: 55 | N32: 58 | O32: 25 | P32: {=O32*9/H32} -> 8.6538462
A33: 임지헌 | B33: 3 | C33: 2 | D33: 0 | E33: 0 | F33: 44 | G33: 26 | H33: 7 | I33: 9 | J33: 0 | K33: 17 | L33: 0 | M33: 10 | N33: 10 | O33: 8 | P33: {=O33*9/H33} -> 10.285714
A34: 류동현 | B34: 3 | C34: 0 | D34: 0 | E34: 0 | F34: 16 | G34: 9 | H34: 2 | I34: 4 | J34: 0 | K34: 6 | L34: 0 | M34: 2 | N34: 6 | O34: 5 | P34: {=O34*9/H34} -> 22.5
A35: 총합 | C35: {=SUM(C29:C34)} -> 6 | D35: {=SUM(D29:D34)} -> 4 | E35: {=SUM(E29:E34)} -> 1 | F35: {=SUM(F29:F34)} -> 279 | G35: {=SUM(G29:G34)} -> 191 | H35: {=SUM(H29:H34)} -> 42.1 | I35: {=SUM(I29:I34)} -> 63 | J35: {=SUM(J29:J34)} -> 0 | ... O35: {=SUM(O29:O34)} -> 41 | P35: {=O35*9/H35} -> 8.7648456

Sheet 22년 드림즈(23')
A1: ◎ 22년 하반기 드림즈리그
A2: 1. 타자 기록
A3: 이름 | B3: 게임수 | C3: 타율 | D3: 타석 | E3: 타수 | F3: 안타 | G3: 1루타 | H3: 2루타 | I3: 3루타 | J3: 홈런 | K3: 득점 | L3: 타점 | M3: 도루 | N3: 사사구 | O3: 삼진 | P3: 장타율 | Q3: 출루율 | R3: OPS
A4: 권강현 | B4: 1 | C4: 0 | D4: 0 | E4: 0 | F4: 0 | G4: 0 | H4: 0 | I4: 0 | J4: 0 | K4: 0 | L4: 0 | M4: 0 | N4: 0 | O4: 0 | P4: 0 | Q4: 0 | R4: {=Q4+P4} -> 0
A5: 권혁진 | B5: 5 | C5: 0.5 | D5: 12 | E5: 8 | F5: 4 | G5: 4 | H5: 0 | I5: 0 | J5: 0 | K5: 3 | L5: 5 | M5: 1 | N5: 4 | O5: 3 | P5: {=(G5*1+H5*2+I5*3+J5*4)/E5} -> 0.5 | Q5: 0.667 | R5: {=Q5+P5} -> 1.167
A6: 김기태 | B6: 6 | C6: 0.417 | D6: 15 | E6: 12 | F6: 5 | G6: 3 | H6: 1 | I6: 1 | J6: 0 | K6: 8 | L6: 7 | M6: 3 | N6: 3 | O6: 2 | P6: {=(G6*1+H6*2+I6*3+J6*4)/E6} -> 0.66666667 | Q6: 0.533 | R6: {=Q6+P6} -> 1.1996667
A7: 김민석 | B7: 1 | C7: 0 | D7: 4 | E7: 4 | F7: 0 | G7: 0 | H7: 0 | I7: 0 | J7: 0 | K7: 0 | L7: 3 | M7: 0 | N7: 0 | O7: 0 | P7: {=(G7*1+H7*2+I7*3+J7*4)/E7} -> 0 | Q7: 0 | R7: {=Q7+P7} -> 0
A8: 김범희 | B8: 7 | C8: 0.455 | D8: 17 | E8: 11 | F8: 5 | G8: 3 | H8: 1 | I8: 1 | J8: 0 | K8: 6 | L8: 4 | M8: 2 | N8: 6 | O8: 1 | P8: {=(G8*1+H8*2+I8*3+J8*4)/E8} -> 0.72727273 | Q8: 0.647 | R8: {=Q8+P8} -> 1.3742727
A9: 김병진 | B9: 6 | C9: 0.091 | D9: 16 | E9: 11 | F9: 1 | G9: 1 | H9: 0 | I9: 0 | J9: 0 | K9: 2 | L9: 2 | M9: 4 | N9: 5 | O9: 9 | P9: {=(G9*1+H9*2+I9*3+J9*4)/E9} -> 0.090909091 | Q9: 0.375 | R9: {=Q9+P9} -> 0.46590909
A10: 김재영 | B10: 6 | C10: 0.75 | D10: 18 | E10: 12 | F10: 9 | G10: 8 | H10: 1 | I10: 0 | J10: 0 | K10: 11 | L10: 8 | M10: 17 | N10: 6 | O10: 0 | P10: {=(G10*1+H10*2+I10*3+J10*4)/E10} -> 0.83333333 | Q10: 0.833 | R10: {=Q10+P10} -> 1.6663333
A11: 김태양 | B11: 6 | C11: 0.231 | D11: 14 | E11: 13 | F11: 3 | G11: 2 | H11: 1 | I11: 0 | J11: 0 | K11: 3 | L11: 4 | M11: 2 | N11: 1 | O11: 4 | P11: {=(G11*1+H11*2+I11*3+J11*4)/E11} -> 0.30769231 | Q11: 0.286 | R11: {=Q11+P11} -> 0.59369231
A12: 김현철 | B12: 0 | C12: 0 | D12: 0 | E12: 0 | F12: 0 | G12: 0 | H12: 0 | I12: 0 | J12: 0 | K12: 0 | L12: 0 | M12: 0 | N12: 0 | O12: 0 | P12: 0 | Q12: 0 | R12: {=Q12+P12} -> 0
A13: 김형준 | B13: 6 | C13: 0.462 | D13: 15 | E13: 13 | F13: 6 | G13: 0 | H13: 5 | I13: 1 | J13: 0 | K13: 5 | L13: 9 | M13: 0 | N13: 2 | O13: 1 | P13: {=(G13*1+H13*2+I13*3+J13*4)/E13} -> 1 | Q13: 0.533 | R13: {=Q13+P13} -> 1.533
A14: 김희제 | B14: 4 | C14: 0 | D14: 9 | E14: 5 | F14: 0 | G14: 0 | H14: 0 | I14: 0 | J14: 0 | K14: 2 | L14: 1 | M14: 1 | N14: 4 | O14: 3 | P14: {=(G14*1+H14*2+I14*3+J14*4)/E14} -> 0 | Q14: 0.444 | R14: {=Q14+P14} -> 0.444
A15: 남동수 | B15: 1 | C15: 0 | D15: 4 | E15: 3 | F15: 0 | G15: 0 | H15: 0 | I15: 0 | J15: 0 | K15: 1 | L15: 0 | M15: 0 | N15: 1 | O15: 2 | P15: {=(G15*1+H15*2+I15*3+J15*4)/E15} -> 0 | Q15: 0.25 | R15: {=Q15+P15} -> 0.25
A16: 류동현 | B16: 5 | C16: 0.2 | D16: 8 | E16: 5 | F16: 1 | G16: 1 | H16: 0 | I16: 0 | J16: 0 | K16: 2 | L16: 1 | M16: 2 | N16: 3 | O16: 1 | P16: {=(G16*1+H16*2+I16*3+J16*4)/E16} -> 0.2 | Q16: 0.5 | R16: {=Q16+P16} -> 0.7
A17: 박영준 | B17: 0 | C17: 0 | D17: 0 | E17: 0 | F17: 0 | G17: 0 | H17: 0 | I17: 0 | J17: 0 | K17: 0 | L17: 0 | M17: 0 | N17: 0 | O17: 0 | P17: 0 | Q17: 0 | R17: {=Q17+P17} -> 0
A18: 박재현 | B18: 5 | C18: 0.429 | D18: 9 | E18: 7 | F18: 3 | G18: 3 | H18: 0 | I18: 0 | J18: 0 | K18: 2 | L18: 2 | M18: 1 | N18: 2 | O18: 2 | P18: {=(G18*1+H18*2+I18*3+J18*4)/E18} -> 0.42857143 | Q18: 0.556 | R18: {=Q18+P18} -> 0.98457143
A19: 백정철 | B19: 1 | C19: 0.5 | D19: 3 | E19: 2 | F19: 1 | G19: 1 | H19: 0 | I19: 0 | J19: 0 | K19: 0 | L19: 0 | M19: 1 | N19: 1 | O19: 1 | P19: {=(G19*1+H19*2+I19*3+J19*4)/E19} -> 0.5 | Q19: 0.667 | R19: {=Q19+P19} -> 1.167
A20: 이동진 | B20: 7 | C20: 0.143 | D20: 14 | E20: 7 | F20: 1 | G20: 1 | H20: 0 | I20: 0 | J20: 0 | K20: 4 | L20: 2 | M20: 4 | N20: 7 | O20: 5 | P20: {=(G20*1+H20*2+I20*3+J20*4)/E20} -> 0.14285714 | Q20: 0.571 | R20: {=Q20+P20} -> 0.71385714
A21: 이철민 | B21: 6 | C21: 0.545 | D21: 15 | E21: 11 | F21: 6 | G21: 4 | H21: 2 | I21: 0 | J21: 0 | K21: 7 | L21: 3 | M21: 5 | N21: 4 | O21: 2 | P21: {=(G21*1+H21*2+I21*3+J21*4)/E21} -> 0.72727273 | Q21: 0.667 | R21: {=Q21+P21} -> 1.3942727
A22: 임지헌 | B22: 3 | C22: 0.167 | D22: 6 | E22: 6 | F22: 1 | G22: 1 | H22: 0 | I22: 0 | J22: 0 | K22: 1 | L22: 1 | M22: 0 | N22: 0 | O22: 3 | P22: {=(G22*1+H22*2+I22*3+J22*4)/E22} -> 0.16666667 | Q22: 0.167 | R22: {=Q22+P22} -> 0.33366667
A23: 조태형 | B23: 5 | C23: 0.2 | D23: 14 | E23: 10 | F23: 2 | G23: 1 | H23: 1 | I23: 0 | J23: 0 | K23: 1 | L23: 5 | M23: 0 | N23: 4 | O23: 5 | P23: {=(G23*1+H23*2+I23*3+J23*4)/E23} -> 0.3 | Q23: 0.429 | R23: {=Q23+P23} -> 0.729
A24: 차현철 | B24: 0 | C24: 0 | D24: 0 | E24: 0 | F24: 0 | G24: 0 | H24: 0 | I24: 0 | J24: 0 | K24: 0 | L24: 0 | M24: 0 | N24: 0 | O24: 0 | P24: 0 | Q24: 0 | R24: {=Q24+P24} -> 0
A25: 총합 | C25: {=F25/E25} -> 0.34285714 | D25: {=SUM(D4:D24)} -> 193 | E25: {=SUM(E4:E24)} -> 140 | F25: {=SUM(F4:F24)} -> 48 | G25: {=SUM(G4:G24)} -> 33 | H25: {=SUM(H4:H24)} -> 12 | I25: {=SUM(I4:I24)} -> 3 | J25: {=SUM(J4:J24)} -> 0 | K25: {=SUM(K4:K24)} -> 58 | ... O25: {=SUM(O4:O24)} -> 44
A27: 2. 투수 기록
A28: 이름 | B28: 게임수 | C28: 승 | D28: 패 | E28: 세 | F28: 타자 | G28: 타수 | H28: 이닝 | I28: 피안타 | J28: 피홈런 | K28: 볼넷 | L28: 사구 | M28: 탈삼진 | N28: 실점 | O28: 자책점 | P28: 방어율
A29: 권강현 | B29: 4 | C29: 1 | D29: 1 | E29: 0 | F29: 38 | G29: {=F29-K29-L29} -> 25 | H29: 4.66666 | I29: 8 | J29: 0 | K29: 11 | L29: 2 | M29: 3 | N29: 14 | O29: 10 | P29: {=O29*9/H29} -> 19.285742
A30: 김병진 | B30: 4 | C30: 0 | D30: 1 | E30: 0 | F30: 28 | G30: {=F30-K30-L30} -> 21 | H30: 2.3333 | I30: 6 | J30: 0 | K30: 6 | L30: 1 | M30: 4 | N30: 12 | O30: 5 | P30: {=O30*9/H30} -> 19.28599
A31: 김형준 | B31: 5 | C31: 1 | D31: 0 | E31: 1 | F31: 41 | G31: {=F31-K31-L31} -> 33 | H31: 7.6666 | I31: 11 | J31: 0 | K31: 5 | L31: 3 | M31: 14 | N31: 13 | O31: 9 | P31: {=O31*9/H31} -> 10.565309
A32: 류동현 | B32: 4 | C32: 0 | D32: 1 | E32: 0 | F32: 62 | G32: {=F32-K32-L32} -> 41 | H32: 7.6666 | I32: 18 | J32: 2 | K32: 18 | L32: 3 | M32: 12 | N32: 26 | O32: 18 | P32: {=O32*9/H32} -> 21.130619
A33: 임지헌 | B33: 2 | C33: 0 | D33: 2 | E33: 0 | F33: 39 | G33: {=F33-K33-L33} -> 21 | H33: 4.3333 | I33: 5 | J33: 1 | K33: 18 | L33: 0 | M33: 3 | N33: 19 | O33: 12 | P33: {=O33*9/H33} -> 24.923269
A34: 조태형 | B34: 4 | C34: 1 | D34: 0 | E34: 2 | F34: 36 | G34: {=F34-K34-L34} -> 29 | H34: 7.3333 | I34: 8 | J34: 1 | K34: 7 | L34: 0 | M34: 8 | N34: 11 | O34: 10 | P34: {=O34*9/H34} -> 12.272783
A35: 총합 | C35: {=SUM(C29:C34)} -> 3 | D35: {=SUM(D29:D34)} -> 5 | E35: {=SUM(E29:E34)} -> 3 | F35: {=SUM(F29:F34)} -> 244 | G35: {=SUM(G29:G34)} -> 170 | H35: {=SUM(H29:H34)} -> 33.99976 | I35: {=SUM(I29:I34)} -> 56 | J35: {=SUM(J29:J34)} -> 4 | ... O35: {=SUM(O29:O34)} -> 64 | P35: {=O35*9/H35} -> 16.941296

Sheet 23년 상반기 코모도(23')
A1: ◎ 23년 상반기 코모도리그
A2: 1. 타자 기록
A3: 선수명 | B3: 경기 | C3: 타율 | D3: 타석 | E3: 타수 | F3: 안타 | G3: 1루타 | H3: 2루타 | I3: 3루타 | J3: 홈런 | K3: 득점 | L3: 타점 | M3: 도루 | N3: 사사구 | O3: 삼진 | P3: 장타율 | Q3: 출루율 | R3: OPS
A4: 권강현 | B4: 2 | C4: 0 | D4: 0 | E4: 0 | F4: 0 | G4: {=F4-(H4+I4+J4)} -> 0 | H4: 0 | I4: 0 | J4: 0 | K4: 0 | L4: 0 | M4: 1 | N4: 0 | O4: 0 | P4: 0 | Q4: 0 | R4: {=Q4+P4} -> 0
A5: 권혁진 | B5: 4 | C5: 0 | D5: 7 | E5: 3 | F5: 0 | G5: {=F5-(H5+I5+J5)} -> 0 | H5: 0 | I5: 0 | J5: 0 | K5: 1 | L5: 0 | M5: 0 | N5: 4 | O5: 0 | P5: {=(G5*1+H5*2+I5*3+J5*4)/E5} -> 0 | Q5: 0.571 | R5: {=Q5+P5} -> 0.571
A6: 김기태 | B6: 9 | C6: 0.474 | D6: 24 | E6: 19 | F6: 9 | G6: {=F6-(H6+I6+J6)} -> 7 | H6: 2 | I6: 0 | J6: 0 | K6: 9 | L6: 9 | M6: 7 | N6: 5 | O6: 2 | P6: {=(G6*1+H6*2+I6*3+J6*4)/E6} -> 0.57894737 | Q6: 0.583 | R6: {=Q6+P6} -> 1.1619474
A7: 김민석 | B7: 0 | C7: 0 | D7: 0 | E7: 0 | F7: 0 | G7: {=F7-(H7+I7+J7)} -> 0 | H7: 0 | I7: 0 | J7: 0 | K7: 0 | L7: 0 | M7: 0 | N7: 0 | O7: 0 | P7: 0 | Q7: 0 | R7: {=Q7+P7} -> 0
A8: 김범희 | B8: 9 | C8: 0.25 | D8: 26 | E8: 20 | F8: 5 | G8: {=F8-(H8+I8+J8)} -> 3 | H8: 0 | I8: 2 | J8: 0 | K8: 7 | L8: 7 | M8: 4 | N8: 6 | O8: 5 | P8: {=(G8*1+H8*2+I8*3+J8*4)/E8} -> 0.45 | Q8: 0.423 | R8: {=Q8+P8} -> 0.873
A9: 김병진 | B9: 4 | C9: 0.2 | D9: 6 | E9: 5 | F9: 1 | G9: {=F9-(H9+I9+J9)} -> 1 | H9: 0 | I9: 0 | J9: 0 | K9: 2 | L9: 0 | M9: 1 | N9: 1 | O9: 1 | P9: {=(G9*1+H9*2+I9*3+J9*4)/E9} -> 0.2 | Q9: 0.333 | R9: {=Q9+P9} -> 0.533
A10: 김재영 | B10: 9 | C10: 0.542 | D10: 31 | E10: 24 | F10: 13 | G10: {=F10-(H10+I10+J10)} -> 9 | H10: 2 | I10: 1 | J10: 1 | K10: 16 | L10: 8 | M10: 16 | N10: 7 | O10: 2 | P10: {=(G10*1+H10*2+I10*3+J10*4)/E10} -> 0.83333333 | Q10: 0.645 | R10: {=Q10+P10} -> 1.4783333
A11: 김태양 | B11: 4 | C11: 0.333 | D11: 7 | E11: 6 | F11: 2 | G11: {=F11-(H11+I11+J11)} -> 2 | H11: 0 | I11: 0 | J11: 0 | K11: 3 | L11: 0 | M11: 3 | N11: 1 | O11: 0 | P11: {=(G11*1+H11*2+I11*3+J11*4)/E11} -> 0.33333333 | Q11: 0.429 | R11: {=Q11+P11} -> 0.76233333
A12: 김현철 | B12: 2 | C12: 0.333 | D12: 3 | E12: 3 | F12: 1 | G12: {=F12-(H12+I12+J12)} -> 1 | H12: 0 | I12: 0 | J12: 0 | K12: 0 | L12: 0 | M12: 1 | N12: 0 | O12: 0 | P12: {=(G12*1+H12*2+I12*3+J12*4)/E12} -> 0.33333333 | Q12: 0.333 | R12: {=Q12+P12} -> 0.66633333
A13: 김형준 | B13: 10 | C13: 0.435 | D13: 25 | E13: 23 | F13: 10 | G13: {=F13-(H13+I13+J13)} -> 6 | H13: 4 | I13: 0 | J13: 0 | K13: 6 | L13: 10 | M13: 5 | N13: 1 | O13: 3 | P13: {=(G13*1+H13*2+I13*3+J13*4)/E13} -> 0.60869565 | Q13: 0.44 | R13: {=Q13+P13} -> 1.0486957
A14: 김희제 | B14: 3 | C14: 0 | D14: 7 | E14: 5 | F14: 0 | G14: {=F14-(H14+I14+J14)} -> 0 | H14: 0 | I14: 0 | J14: 0 | K14: 2 | L14: 0 | M14: 1 | N14: 2 | O14: 3 | P14: {=(G14*1+H14*2+I14*3+J14*4)/E14} -> 0 | Q14: 0.286 | R14: {=Q14+P14} -> 0.286
A15: 남동수 | B15: 6 | C15: 0.222 | D15: 13 | E15: 9 | F15: 2 | G15: {=F15-(H15+I15+J15)} -> 2 | H15: 0 | I15: 0 | J15: 0 | K15: 1 | L15: 3 | M15: 1 | N15: 3 | O15: 5 | P15: {=(G15*1+H15*2+I15*3+J15*4)/E15} -> 0.22222222 | Q15: 0.417 | R15: {=Q15+P15} -> 0.63922222
A16: 류동현 | B16: 2 | C16: 0 | D16: 1 | E16: 1 | F16: 0 | G16: {=F16-(H16+I16+J16)} -> 0 | H16: 0 | I16: 0 | J16: 0 | K16: 0 | L16: 0 | M16: 0 | N16: 0 | O16: 0 | P16: {=(G16*1+H16*2+I16*3+J16*4)/E16} -> 0 | Q16: 0 | R16: {=Q16+P16} -> 0
A17: 박영준 | B17: 2 | C17: 0 | D17: 5 | E17: 3 | F17: 0 | G17: {=F17-(H17+I17+J17)} -> 0 | H17: 0 | I17: 0 | J17: 0 | K17: 2 | L17: 0 | M17: 2 | N17: 2 | O17: 1 | P17: {=(G17*1+H17*2+I17*3+J17*4)/E17} -> 0 | Q17: 0.4 | R17: {=Q17+P17} -> 0.4
A18: 박재현 | B18: 7 | C18: 0.611 | D18: 21 | E18: 18 | F18: 11 | G18: {=F18-(H18+I18+J18)} -> 10 | H18: 0 | I18: 0 | J18: 1 | K18: 6 | L18: 6 | M18: 3 | N18: 3 | O18: 2 | P18: {=(G18*1+H18*2+I18*3+J18*4)/E18} -> 0.77777778 | Q18: 0.667 | R18: {=Q18+P18} -> 1.4447778
A19: 백정철 | B19: 6 | C19: 0.286 | D19: 15 | E19: 14 | F19: 4 | G19: {=F19-(H19+I19+J19)} -> 4 | H19: 0 | I19: 0 | J19: 0 | K19: 2 | L19: 3 | M19: 2 | N19: 0 | O19: 1 | P19: {=(G19*1+H19*2+I19*3+J19*4)/E19} -> 0.28571429 | Q19: 0.267 | R19: {=Q19+P19} -> 0.55271429
... A23: 조태형 | B23: 5 | C23: 0.4 | D23: 14 | E23: 10 | F23: 4 | G23: {=F23-(H23+I23+J23)} -> 4 | H23: 0 | I23: 0 | J23: 0 | K23: 4 | L23: 0 | M23: 4 | N23: 4 | O23: 2 | P23: {=(G23*1+H23*2+I23*3+J23*4)/E23} -> 0.4 | Q23: 0.571 | R23: {=Q23+P23} -> 0.971
A24: 차현철 | B24: 5 | C24: 0 | D24: 9 | E24: 7 | F24: 0 | G24: {=F24-(H24+I24+J24)} -> 0 | H24: 0 | I24: 0 | J24: 0 | K24: 1 | L24: 0 | M24: 0 | N24: 2 | O24: 1 | P24: 0 | Q24: 0.222 | R24: {=Q24+P24} -> 0.222
A25: 총합 | C25: {=F25/E25} -> 0.35748792 | D25: {=SUM(D4:D24)} -> 256 | E25: {=SUM(E4:E24)} -> 207 | F25: {=SUM(F4:F24)} -> 74 | G25: {=SUM(G4:G24)} -> 59 | H25: {=SUM(H4:H24)} -> 9 | I25: {=SUM(I4:I24)} -> 3 | J25: {=SUM(J4:J24)} -> 3 | K25: {=SUM(K4:K24)} -> 75 | ... O25: {=SUM(O4:O24)} -> 34
A27: 2. 투수 기록
A28: 선수명 | B28: 경기 | C28: 승 | D28: 패 | E28: 세 | F28: 타자 | G28: 타수 | H28: 이닝 | I28: 피안타 | J28: 피홈런 | K28: BB | L28: HP | M28: 삼진 | N28: 실점 | O28: 자책 | P28: 방어율
A29: 권강현 | B29: 3 | C29: 0 | D29: 0 | E29: 0 | F29: 12 | G29: {=F29-K29-L29} -> 7 | H29: 0.66666667 | I29: 2 | J29: 0 | K29: 5 | L29: 0 | M29: 1 | N29: 4 | O29: 1 | P29: {=O29*9/H29} -> 13.5
A30: 김병진 | B30: 5 | C30: 1 | D30: 1 | E30: 0 | F30: 85 | G30: {=F30-K30-L30} -> 64 | H30: 10.333333 | I30: 27 | J30: 3 | K30: 17 | L30: 4 | M30: 7 | N30: 36 | O30: 27 | P30: {=O30*9/H30} -> 23.516129
A31: 김형준 | B31: 6 | C31: 0 | D31: 2 | E31: 0 | F31: 54 | G31: {=F31-K31-L31} -> 49 | H31: 9.3333333 | I31: 13 | J31: 0 | K31: 5 | L31: 0 | M31: 17 | N31: 12 | O31: 4 | P31: {=O31*9/H31} -> 3.8571429
A32: 류동현 | B32: 3 | C32: 0 | D32: 1 | E32: 0 | F32: 33 | G32: {=F32-K32-L32} -> 25 | H32: 4.6666667 | I32: 7 | J32: 0 | K32: 8 | L32: 0 | M32: 2 | N32: 11 | O32: 5 | P32: {=O32*9/H32} -> 9.6428571
